Workbook

Sheet Mode d'emploi
B1: Tableau de suivi hebdomadaire des courriers arrivés
B3: Objet
B4: Enregistrer chaque courrier arrivé au ministère et obtenir automatiquement le point hebdomadaire (volumes, imputations, traitement, retards).
B6: Onglets
B7: • Registre : une ligne par courrier reçu (jusqu'à 1 000 lignes préparées). Les lignes 5 à 16 contiennent des exemples à remplacer.
B8: • Point hebdomadaire : saisir une date dans la cellule jaune D3 ; tous les tableaux se recalculent pour la semaine (lundi → dimanche).
B9: • Synthèse annuelle : vue des 52/53 semaines de l'année choisie dans Paramètres, avec graphique d'évolution.
B10: • Paramètres : listes déroulantes (services, types, statuts…) et délais de traitement par priorité, à adapter au ministère.
B12: Code couleur
B13: • Cellules jaunes, texte bleu : à saisir. • Cellules grises : calculées automatiquement, ne pas modifier.
B14: • « En retard ? » = OUI (rouge) lorsque la date limite est dépassée et que le courrier n'est pas traité ; « Traité hors délai » (orange) sinon.
B16: Règles de calcul
... B25: 4. Chaque vendredi : ouvrir « Point hebdomadaire », saisir une date de la semaine, compléter les observations, imprimer ou exporter en PDF.

Sheet Registre
A1: Registre des courriers arrivés
A2: Une ligne par courrier. Cellules jaunes = à saisir · cellules grises = calculées automatiquement (ne pas modifier). Les lignes 5 à 16 sont des exemples à remplacer.
A3: Saisie
A4: N° d'ordre | B4: Date d'arrivée | C4: Semaine n° | D4: Semaine du (lundi) | E4: Réf. du courrier | F4: Date du courrier | G4: Expéditeur | H4: Catégorie expéditeur | I4: Objet | J4: Type de courrier | K4: Mode de réception | L4: Priorité | M4: Service imputé | N4: Date d'imputation | O4: Délai (jours) | P4: Date limite | Q4: Statut | R4: Date de traitement | S4: Durée de traitement (jours) | T4: En retard ? | U4: Observations
A5: =IF(B5="","",YEAR(B5)&"/"&TEXT(ROW()-4,"0000")) -> 2026/0001 | B5: 46279 | C5: =IF(B5="","",INT((B5-DATE(YEAR(B5-WEEKDAY(B5-1)+4),1,3)+WEEKDAY(DATE(YEAR(B5-WEEKDAY(B5-1)+4),1,3))+5)/7)) -> 38 | D5: =IF(B5="","",B5-WEEKDAY(B5,2)+1) -> 46279 | E5: N°0412/MEF/SG | F5: 46275 | G5: Ministère de l'Économie et des Finances | H5: Administration publique | I5: Transmission du calendrier budgétaire 2027 | J5: Lettre | K5: Valise / Coursier | L5: Urgent | M5: Direction des Affaires Administratives et Financières | N5: 46279 | O5: =IF(L5="","",IFERROR(VLOOKUP(L5,Paramètres!$F$5:$G$8,2,FALSE()),"")) -> 5 | P5: =IF(OR(B5="",O5=""),"",IF(N5="",B5,N5)+O5) -> 46284 | Q5: Traité | R5: 46283 | S5: =IF(OR(B5="",R5=""),"",R5-B5) -> 4 | T5: =IF(OR(B5="",P5=""),"",IF(R5<>"",IF(R5>P5,"Traité hors délai","Non"),IF(Q5="Classé sans suite","Non",IF(TODAY()>P5,"OUI","Non")))) -> Non
A6: =IF(B6="","",YEAR(B6)&"/"&TEXT(ROW()-4,"0000")) -> 2026/0002 | B6: 46280 | C6: =IF(B6="","",INT((B6-DATE(YEAR(B6-WEEKDAY(B6-1)+4),1,3)+WEEKDAY(DATE(YEAR(B6-WEEKDAY(B6-1)+4),1,3))+5)/7)) -> 38 | D6: =IF(B6="","",B6-WEEKDAY(B6,2)+1) -> 46279 | E6: s/n | F6: 46277 | G6: M. Kouassi Yao | H6: Particulier | I6: Demande de stage | J6: Demande | K6: Dépôt physique | L6: Normal | M6: Direction des Ressources Humaines | N6: 46281 | O6: =IF(L6="","",IFERROR(VLOOKUP(L6,Paramètres!$F$5:$G$8,2,FALSE()),"")) -> 15 | P6: =IF(OR(B6="",O6=""),"",IF(N6="",B6,N6)+O6) -> 46296 | Q6: Traité | R6: 46290 | S6: =IF(OR(B6="",R6=""),"",R6-B6) -> 10 | T6: =IF(OR(B6="",P6=""),"",IF(R6<>"",IF(R6>P6,"Traité hors délai","Non"),IF(Q6="Classé sans suite","Non",IF(TODAY()>P6,"OUI","Non")))) -> Non
A7: =IF(B7="","",YEAR(B7)&"/"&TEXT(ROW()-4,"0000")) -> 2026/0003 | B7: 46281 | C7: =IF(B7="","",INT((B7-DATE(YEAR(B7-WEEKDAY(B7-1)+4),1,3)+WEEKDAY(DATE(YEAR(B7-WEEKDAY(B7-1)+4),1,3))+5)/7)) -> 38 | D7: =IF(B7="","",B7-WEEKDAY(B7,2)+1) -> 46279 | E7: AN/CF/2026-118 | F7: 46280 | G7: Assemblée Nationale – Commission des Finances | H7: Institution / Parlement | I7: Convocation audition du Ministre | J7: Convocation | K7: Courrier postal | L7: Très urgent | M7: Cabinet du Ministre | N7: 46281 | O7: =IF(L7="","",IFERROR(VLOOKUP(L7,Paramètres!$F$5:$G$8,2,FALSE()),"")) -> 2 | P7: =IF(OR(B7="",O7=""),"",IF(N7="",B7,N7)+O7) -> 46283 | Q7: Traité | R7: 46282 | S7: =IF(OR(B7="",R7=""),"",R7-B7) -> 1 | T7: =IF(OR(B7="",P7=""),"",IF(R7<>"",IF(R7>P7,"Traité hors délai","Non"),IF(Q7="Classé sans suite","Non",IF(TODAY()>P7,"OUI","Non")))) -> Non
A8: =IF(B8="","",YEAR(B8)&"/"&TEXT(ROW()-4,"0000")) -> 2026/0004 | B8: 46282 | C8: =IF(B8="","",INT((B8-DATE(YEAR(B8-WEEKDAY(B8-1)+4),1,3)+WEEKDAY(DATE(YEAR(B8-WEEKDAY(B8-1)+4),1,3))+5)/7)) -> 38 | D8: =IF(B8="","",B8-WEEKDAY(B8,2)+1) -> 46279 | E8: UE/DEL/2026/553 | F8: 46279 | G8: Délégation de l'Union européenne | H8: Partenaire technique et financier | I8: Rapport de mission de suivi du projet | J8: Rapport | K8: Courriel | L8: Normal | M8: Direction de la Planification et des Études | N8: 46283 | O8: =IF(L8="","",IFERROR(VLOOKUP(L8,Paramètres!$F$5:$G$8,2,FALSE()),"")) -> 15 | P8: =IF(OR(B8="",O8=""),"",IF(N8="",B8,N8)+O8) -> 46298 | Q8: En cours | S8: =IF(OR(B8="",R8=""),"",R8-B8) | T8: =IF(OR(B8="",P8=""),"",IF(R8<>"",IF(R8>P8,"Traité hors délai","Non"),IF(Q8="Classé sans suite","Non",IF(TODAY()>P8,"OUI","Non")))) -> Non
A9: =IF(B9="","",YEAR(B9)&"/"&TEXT(ROW()-4,"0000")) -> 2026/0005 | B9: 46283 | C9: =IF(B9="","",INT((B9-DATE(YEAR(B9-WEEKDAY(B9-1)+4),1,3)+WEEKDAY(DATE(YEAR(B9-WEEKDAY(B9-1)+4),1,3))+5)/7)) -> 38 | D9: =IF(B9="","",B9-WEEKDAY(B9,2)+1) -> 46279 | E9: FAC-2026-0981 | F9: 46276 | G9: Société SOGEBAT | H9: Entreprise | I9: Facture travaux de réhabilitation | J9: Facture | K9: Dépôt physique | L9: Normal | M9: Direction des Affaires Administratives et Financières | N9: 46286 | O9: =IF(L9="","",IFERROR(VLOOKUP(L9,Paramètres!$F$5:$G$8,2,FALSE()),"")) -> 15 | P9: =IF(OR(B9="",O9=""),"",IF(N9="",B9,N9)+O9) -> 46301 | Q9: Traité | R9: 46296 | S9: =IF(OR(B9="",R9=""),"",R9-B9) -> 13 | T9: =IF(OR(B9="",P9=""),"",IF(R9<>"",IF(R9>P9,"Traité hors délai","Non"),IF(Q9="Classé sans suite","Non",IF(TODAY()>P9,"OUI","Non")))) -> Non
A10: =IF(B10="","",YEAR(B10)&"/"&TEXT(ROW()-4,"0000")) -> 2026/0006 | B10: 46286 | C10: =IF(B10="","",INT((B10-DATE(YEAR(B10-WEEKDAY(B10-1)+4),1,3)+WEEKDAY(DATE(YEAR(B10-WEEKDAY(B10-1)+4),1,3))+5)/7)) -> 39 | D10: =IF(B10="","",B10-WEEKDAY(B10,2)+1) -> 46286 | E10: ONG/AV/045 | F10: 46283 | G10: ONG Agir Ensemble | H10: Association / ONG | I10: Invitation à l'atelier de validation | J10: Invitation | K10: Courriel | L10: Pour information | M10: Direction de la Communication | N10: 46286 | O10: =IF(L10="","",IFERROR(VLOOKUP(L10,Paramètres!$F$5:$G$8,2,FALSE()),"")) -> 30 | P10: =IF(OR(B10="",O10=""),"",IF(N10="",B10,N10)+O10) -> 46316 | Q10: Classé sans suite | S10: =IF(OR(B10="",R10=""),"",R10-B10) | T10: =IF(OR(B10="",P10=""),"",IF(R10<>"",IF(R10>P10,"Traité hors délai","Non"),IF(Q10="Classé sans suite","Non",IF(TODAY()>P10,"OUI","Non")))) -> Non | U10: Pour information
A11: =IF(B11="","",YEAR(B11)&"/"&TEXT(ROW()-4,"0000")) -> 2026/0007 | B11: 46287 | C11: =IF(B11="","",INT((B11-DATE(YEAR(B11-WEEKDAY(B11-1)+4),1,3)+WEEKDAY(DATE(YEAR(B11-WEEKDAY(B11-1)+4),1,3))+5)/7)) -> 39 | D11: =IF(B11="","",B11-WEEKDAY(B11,2)+1) -> 46286 | E11: PM/SGG/2026-77 | F11: 46286 | G11: Primature – Secrétariat Général du Gouvernement | H11: Administration publique | I11: Circulaire relative à la préparation du Conseil des Ministres | J11: Circulaire | K11: Valise / Coursier | L11: Très urgent | M11: Secrétariat Général | N11: 46287 | O11: =IF(L11="","",IFERROR(VLOOKUP(L11,Paramètres!$F$5:$G$8,2,FALSE()),"")) -> 2 | P11: =IF(OR(B11="",O11=""),"",IF(N11="",B11,N11)+O11) -> 46289 | Q11: En cours | S11: =IF(OR(B11="",R11=""),"",R11-B11) | T11: =IF(OR(B11="",P11=""),"",IF(R11<>"",IF(R11>P11,"Traité hors délai","Non"),IF(Q11="Classé sans suite","Non",IF(TODAY()>P11,"OUI","Non")))) -> OUI | U11: Relance faite le 28/09
A12: =IF(B12="","",YEAR(B12)&"/"&TEXT(ROW()-4,"0000")) -> 2026/0008 | B12: 46288 | C12: =IF(B12="","",INT((B12-DATE(YEAR(B12-WEEKDAY(B12-1)+4),1,3)+WEEKDAY(DATE(YEAR(B12-WEEKDAY(B12-1)+4),1,3))+5)/7)) -> 39 | D12: =IF(B12="","",B12-WEEKDAY(B12,2)+1) -> 46286 | E12: s/n | F12: 46285 | G12: Mme Diallo Aminata | H12: Particulier | I12: Réclamation relative au paiement de pension | J12: Réclamation | K12: Courrier postal | L12: Urgent | M12: Direction des Affaires Juridiques | N12: 46289 | O12: =IF(L12="","",IFERROR(VLOOKUP(L12,Paramètres!$F$5:$G$8,2,FALSE()),"")) -> 5 | P12: =IF(OR(B12="",O12=""),"",IF(N12="",B12,N12)+O12) -> 46294 | Q12: Imputé | S12: =IF(OR(B12="",R12=""),"",R12-B12) | T12: =IF(OR(B12="",P12=""),"",IF(R12<>"",IF(R12>P12,"Traité hors délai","Non"),IF(Q12="Classé sans suite","Non",IF(TODAY()>P12,"OUI","Non")))) -> OUI
A13: =IF(B13="","",YEAR(B13)&"/"&TEXT(ROW()-4,"0000")) -> 2026/0009 | B13: 46289 | C13: =IF(B13="","",INT((B13-DATE(YEAR(B13-WEEKDAY(B13-1)+4),1,3)+WEEKDAY(DATE(YEAR(B13-WEEKDAY(B13-1)+4),1,3))+5)/7)) -> 39 | D13: =IF(B13="","",B13-WEEKDAY(B13,2)+1) -> 46286 | E13: IGE/2026/31 | F13: 46288 | G13: Inspection Générale d'État | H13: Administration publique | I13: Demande de pièces justificatives – audit 2025 | J13: Demande | K13: Dépôt physique | L13: Urgent | M13: Inspection Générale | N13: 46289 | O13: =IF(L13="","",IFERROR(VLOOKUP(L13,Paramètres!$F$5:$G$8,2,FALSE()),"")) -> 5 | P13: =IF(OR(B13="",O13=""),"",IF(N13="",B13,N13)+O13) -> 46294 | Q13: Traité | R13: 46294 | S13: =IF(OR(B13="",R13=""),"",R13-B13) -> 5 | T13: =IF(OR(B13="",P13=""),"",IF(R13<>"",IF(R13>P13,"Traité hors délai","Non"),IF(Q13="Classé sans suite","Non",IF(TODAY()>P13,"OUI","Non")))) -> Non
A14: =IF(B14="","",YEAR(B14)&"/"&TEXT(ROW()-4,"0000")) -> 2026/0010 | B14: 46293 | C14: =IF(B14="","",INT((B14-DATE(YEAR(B14-WEEKDAY(B14-1)+4),1,3)+WEEKDAY(DATE(YEAR(B14-WEEKDAY(B14-1)+4),1,3))+5)/7)) -> 40 | D14: =IF(B14="","",B14-WEEKDAY(B14,2)+1) -> 46293 | E14: BM/2026/1207 | F14: 46290 | G14: Banque mondiale | H14: Partenaire technique et financier | I14: Avis de non-objection – plan de passation | J14: Lettre | K14: Courriel | L14: Urgent | M14: Direction de la Planification et des Études | N14: 46293 | O14: =IF(L14="","",IFERROR(VLOOKUP(L14,Paramètres!$F$5:$G$8,2,FALSE()),"")) -> 5 | P14: =IF(OR(B14="",O14=""),"",IF(N14="",B14,N14)+O14) -> 46298 | Q14: En cours | S14: =IF(OR(B14="",R14=""),"",R14-B14) | T14: =IF(OR(B14="",P14=""),"",IF(R14<>"",IF(R14>P14,"Traité hors délai","Non"),IF(Q14="Classé sans suite","Non",IF(TODAY()>P14,"OUI","Non")))) -> Non
A15: =IF(B15="","",YEAR(B15)&"/"&TEXT(ROW()-4,"0000")) -> 2026/0011 | B15: 46294 | C15: =IF(B15="","",INT((B15-DATE(YEAR(B15-WEEKDAY(B15-1)+4),1,3)+WEEKDAY(DATE(YEAR(B15-WEEKDAY(B15-1)+4),1,3))+5)/7)) -> 40 | D15: =IF(B15="","",B15-WEEKDAY(B15,2)+1) -> 46293 | E15: DRH/NS/2026-14 | F15: 46294 | G15: Direction des Ressources Humaines | H15: Administration publique | I15: Note de service – congés administratifs | J15: Note de service | K15: Dépôt physique | L15: Pour information | M15: Secrétariat Général | N15: 46294 | O15: =IF(L15="","",IFERROR(VLOOKUP(L15,Paramètres!$F$5:$G$8,2,FALSE()),"")) -> 30 | P15: =IF(OR(B15="",O15=""),"",IF(N15="",B15,N15)+O15) -> 46324 | Q15: Traité | R15: 46295 | S15: =IF(OR(B15="",R15=""),"",R15-B15) -> 1 | T15: =IF(OR(B15="",P15=""),"",IF(R15<>"",IF(R15>P15,"Traité hors délai","Non"),IF(Q15="Classé sans suite","Non",IF(TODAY()>P15,"OUI","Non")))) -> Non
A16: =IF(B16="","",YEAR(B16)&"/"&TEXT(ROW()-4,"0000")) -> 2026/0012 | B16: 46295 | C16: =IF(B16="","",INT((B16-DATE(YEAR(B16-WEEKDAY(B16-1)+4),1,3)+WEEKDAY(DATE(YEAR(B16-WEEKDAY(B16-1)+4),1,3))+5)/7)) -> 40 | D16: =IF(B16="","",B16-WEEKDAY(B16,2)+1) -> 46293 | E16: s/n | F16: 46292 | G16: Syndicat national des agents | H16: Association / ONG | I16: Demande d'audience | J16: Demande | K16: Dépôt physique | L16: Normal | M16: Cabinet du Ministre | O16: =IF(L16="","",IFERROR(VLOOKUP(L16,Paramètres!$F$5:$G$8,2,FALSE()),"")) -> 15 | P16: =IF(OR(B16="",O16=""),"",IF(N16="",B16,N16)+O16) -> 46310 | Q16: Reçu | S16: =IF(OR(B16="",R16=""),"",R16-B16) | T16: =IF(OR(B16="",P16=""),"",IF(R16<>"",IF(R16>P16,"Traité hors délai","Non"),IF(Q16="Classé sans suite","Non",IF(TODAY()>P16,"OUI","Non")))) -> Non | U16: En attente d'imputation
A17: =IF(B17="","",YEAR(B17)&"/"&TEXT(ROW()-4,"0000")) | C17: =IF(B17="","",INT((B17-DATE(YEAR(B17-WEEKDAY(B17-1)+4),1,3)+WEEKDAY(DATE(YEAR(B17-WEEKDAY(B17-1)+4),1,3))+5)/7)) | D17: =IF(B17="","",B17-WEEKDAY(B17,2)+1) | O17: =IF(L17="","",IFERROR(VLOOKUP(L17,Paramètres!$F$5:$G$8,2,FALSE()),"")) | P17: =IF(OR(B17="",O17=""),"",IF(N17="",B17,N17)+O17) | S17: =IF(OR(B17="",R17=""),"",R17-B17) | T17: =IF(OR(B17="",P17=""),"",IF(R17<>"",IF(R17>P17,"Traité hors délai","Non"),IF(Q17="Classé sans suite","Non",IF(TODAY()>P17,"OUI","Non"))))
A18: =IF(B18="","",YEAR(B18)&"/"&TEXT(ROW()-4,"0000")) | C18: =IF(B18="","",INT((B18-DATE(YEAR(B18-WEEKDAY(B18-1)+4),1,3)+WEEKDAY(DATE(YEAR(B18-WEEKDAY(B18-1)+4),1,3))+5)/7)) | D18: =IF(B18="","",B18-WEEKDAY(B18,2)+1) | O18: =IF(L18="","",IFERROR(VLOOKUP(L18,Paramètres!$F$5:$G$8,2,FALSE()),"")) | P18: =IF(OR(B18="",O18=""),"",IF(N18="",B18,N18)+O18) | S18: =IF(OR(B18="",R18=""),"",R18-B18) | T18: =IF(OR(B18="",P18=""),"",IF(R18<>"",IF(R18>P18,"Traité hors délai","Non"),IF(Q18="Classé sans suite","Non",IF(TODAY()>P18,"OUI","Non"))))
A19: =IF(B19="","",YEAR(B19)&"/"&TEXT(ROW()-4,"0000")) | C19: =IF(B19="","",INT((B19-DATE(YEAR(B19-WEEKDAY(B19-1)+4),1,3)+WEEKDAY(DATE(YEAR(B19-WEEKDAY(B19-1)+4),1,3))+5)/7)) | D19: =IF(B19="","",B19-WEEKDAY(B19,2)+1) | O19: =IF(L19="","",IFERROR(VLOOKUP(L19,Paramètres!$F$5:$G$8,2,FALSE()),"")) | P19: =IF(OR(B19="",O19=""),"",IF(N19="",B19,N19)+O19) | S19: =IF(OR(B19="",R19=""),"",R19-B19) | T19: =IF(OR(B19="",P19=""),"",IF(R19<>"",IF(R19>P19,"Traité hors délai","Non"),IF(Q19="Classé sans suite","Non",IF(TODAY()>P19,"OUI","Non"))))
A20: =IF(B20="","",YEAR(B20)&"/"&TEXT(ROW()-4,"0000")) | C20: =IF(B20="","",INT((B20-DATE(YEAR(B20-WEEKDAY(B20-1)+4),1,3)+WEEKDAY(DATE(YEAR(B20-WEEKDAY(B20-1)+4),1,3))+5)/7)) | D20: =IF(B20="","",B20-WEEKDAY(B20,2)+1) | O20: =IF(L20="","",IFERROR(VLOOKUP(L20,Paramètres!$F$5:$G$8,2,FALSE()),"")) | P20: =IF(OR(B20="",O20=""),"",IF(N20="",B20,N20)+O20) | S20: =IF(OR(B20="",R20=""),"",R20-B20) | T20: =IF(OR(B20="",P20=""),"",IF(R20<>"",IF(R20>P20,"Traité hors délai","Non"),IF(Q20="Classé sans suite","Non",IF(TODAY()>P20,"OUI","Non"))))
A21: =IF(B21="","",YEAR(B21)&"/"&TEXT(ROW()-4,"0000")) | C21: =IF(B21="","",INT((B21-DATE(YEAR(B21-WEEKDAY(B21-1)+4),1,3)+WEEKDAY(DATE(YEAR(B21-WEEKDAY(B21-1)+4),1,3))+5)/7)) | D21: =IF(B21="","",B21-WEEKDAY(B21,2)+1) | O21: =IF(L21="","",IFERROR(VLOOKUP(L21,Paramètres!$F$5:$G$8,2,FALSE()),"")) | P21: =IF(OR(B21="",O21=""),"",IF(N21="",B21,N21)+O21) | S21: =IF(OR(B21="",R21=""),"",R21-B21) | T21: =IF(OR(B21="",P21=""),"",IF(R21<>"",IF(R21>P21,"Traité hors délai","Non"),IF(Q21="Classé sans suite","Non",IF(TODAY()>P21,"OUI","Non"))))
A22: =IF(B22="","",YEAR(B22)&"/"&TEXT(ROW()-4,"0000")) | C22: =IF(B22="","",INT((B22-DATE(YEAR(B22-WEEKDAY(B22-1)+4),1,3)+WEEKDAY(DATE(YEAR(B22-WEEKDAY(B22-1)+4),1,3))+5)/7)) | D22: =IF(B22="","",B22-WEEKDAY(B22,2)+1) | O22: =IF(L22="","",IFERROR(VLOOKUP(L22,Paramètres!$F$5:$G$8,2,FALSE()),"")) | P22: =IF(OR(B22="",O22=""),"",IF(N22="",B22,N22)+O22) | S22: =IF(OR(B22="",R22=""),"",R22-B22) | T22: =IF(OR(B22="",P22=""),"",IF(R22<>"",IF(R22>P22,"Traité hors délai","Non"),IF(Q22="Classé sans suite","Non",IF(TODAY()>P22,"OUI","Non"))))
A23: =IF(B23="","",YEAR(B23)&"/"&TEXT(ROW()-4,"0000")) | C23: =IF(B23="","",INT((B23-DATE(YEAR(B23-WEEKDAY(B23-1)+4),1,3)+WEEKDAY(DATE(YEAR(B23-WEEKDAY(B23-1)+4),1,3))+5)/7)) | D23: =IF(B23="","",B23-WEEKDAY(B23,2)+1) | O23: =IF(L23="","",IFERROR(VLOOKUP(L23,Paramètres!$F$5:$G$8,2,FALSE()),"")) | P23: =IF(OR(B23="",O23=""),"",IF(N23="",B23,N23)+O23) | S23: =IF(OR(B23="",R23=""),"",R23-B23) | T23: =IF(OR(B23="",P23=""),"",IF(R23<>"",IF(R23>P23,"Traité hors délai","Non"),IF(Q23="Classé sans suite","Non",IF(TODAY()>P23,"OUI","Non"))))
A24: =IF(B24="","",YEAR(B24)&"/"&TEXT(ROW()-4,"0000")) | C24: =IF(B24="","",INT((B24-DATE(YEAR(B24-WEEKDAY(B24-1)+4),1,3)+WEEKDAY(DATE(YEAR(B24-WEEKDAY(B24-1)+4),1,3))+5)/7)) | D24: =IF(B24="","",B24-WEEKDAY(B24,2)+1) | O24: =IF(L24="","",IFERROR(VLOOKUP(L24,Paramètres!$F$5:$G$8,2,FALSE()),"")) | P24: =IF(OR(B24="",O24=""),"",IF(N24="",B24,N24)+O24) | S24: =IF(OR(B24="",R24=""),"",R24-B24) | T24: =IF(OR(B24="",P24=""),"",IF(R24<>"",IF(R24>P24,"Traité hors délai","Non"),IF(Q24="Classé sans suite","Non",IF(TODAY()>P24,"OUI","Non"))))
A25: =IF(B25="","",YEAR(B25)&"/"&TEXT(ROW()-4,"0000")) | C25: =IF(B25="","",INT((B25-DATE(YEAR(B25-WEEKDAY(B25-1)+4),1,3)+WEEKDAY(DATE(YEAR(B25-WEEKDAY(B25-1)+4),1,3))+5)/7)) | D25: =IF(B25="","",B25-WEEKDAY(B25,2)+1) | O25: =IF(L25="","",IFERROR(VLOOKUP(L25,Paramètres!$F$5:$G$8,2,FALSE()),"")) | P25: =IF(OR(B25="",O25=""),"",IF(N25="",B25,N25)+O25) | S25: =IF(OR(B25="",R25=""),"",R25-B25) | T25: =IF(OR(B25="",P25=""),"",IF(R25<>"",IF(R25>P25,"Traité hors délai","Non"),IF(Q25="Classé sans suite","Non",IF(TODAY()>P25,"OUI","Non"))))
A26: =IF(B26="","",YEAR(B26)&"/"&TEXT(ROW()-4,"0000")) | C26: =IF(B26="","",INT((B26-DATE(YEAR(B26-WEEKDAY(B26-1)+4),1,3)+WEEKDAY(DATE(YEAR(B26-WEEKDAY(B26-1)+4),1,3))+5)/7)) | D26: =IF(B26="","",B26-WEEKDAY(B26,2)+1) | O26: =IF(L26="","",IFERROR(VLOOKUP(L26,Paramètres!$F$5:$G$8,2,FALSE()),"")) | P26: =IF(OR(B26="",O26=""),"",IF(N26="",B26,N26)+O26) | S26: =IF(OR(B26="",R26=""),"",R26-B26) | T26: =IF(OR(B26="",P26=""),"",IF(R26<>"",IF(R26>P26,"Traité hors délai","Non"),IF(Q26="Classé sans suite","Non",IF(TODAY()>P26,"OUI","Non"))))
A27: =IF(B27="","",YEAR(B27)&"/"&TEXT(ROW()-4,"0000")) | C27: =IF(B27="","",INT((B27-DATE(YEAR(B27-WEEKDAY(B27-1)+4),1,3)+WEEKDAY(DATE(YEAR(B27-WEEKDAY(B27-1)+4),1,3))+5)/7)) | D27: =IF(B27="","",B27-WEEKDAY(B27,2)+1) | O27: =IF(L27="","",IFERROR(VLOOKUP(L27,Paramètres!$F$5:$G$8,2,FALSE()),"")) | P27: =IF(OR(B27="",O27=""),"",IF(N27="",B27,N27)+O27) | S27: =IF(OR(B27="",R27=""),"",R27-B27) | T27: =IF(OR(B27="",P27=""),"",IF(R27<>"",IF(R27>P27,"Traité hors délai","Non"),IF(Q27="Classé sans suite","Non",IF(TODAY()>P27,"OUI","Non"))))
A28: =IF(B28="","",YEAR(B28)&"/"&TEXT(ROW()-4,"0000")) | C28: =IF(B28="","",INT((B28-DATE(YEAR(B28-WEEKDAY(B28-1)+4),1,3)+WEEKDAY(DATE(YEAR(B28-WEEKDAY(B28-1)+4),1,3))+5)/7)) | D28: =IF(B28="","",B28-WEEKDAY(B28,2)+1) | O28: =IF(L28="","",IFERROR(VLOOKUP(L28,Paramètres!$F$5:$G$8,2,FALSE()),"")) | P28: =IF(OR(B28="",O28=""),"",IF(N28="",B28,N28)+O28) | S28: =IF(OR(B28="",R28=""),"",R28-B28) | T28: =IF(OR(B28="",P28=""),"",IF(R28<>"",IF(R28>P28,"Traité hors délai","Non"),IF(Q28="Classé sans suite","Non",IF(TODAY()>P28,"OUI","Non"))))
... A1004: =IF(B1004="","",YEAR(B1004)&"/"&TEXT(ROW()-4,"0000")) | C1004: =IF(B1004="","",INT((B1004-DATE(YEAR(B1004-WEEKDAY(B1004-1)+4),1,3)+WEEKDAY(DATE(YEAR(B1004-WEEKDAY(B1004-1)+4),1,3))+5)/7)) | D1004: =IF(B1004="","",B1004-WEEKDAY(B1004,2)+1) | O1004: =IF(L1004="","",IFERROR(VLOOKUP(L1004,Paramètres!$F$5:$G$8,2,FALSE()),"")) | P1004: =IF(OR(B1004="",O1004=""),"",IF(N1004="",B1004,N1004)+O1004) | S1004: =IF(OR(B1004="",R1004=""),"",R1004-B1004) | T1004: =IF(OR(B1004="",P1004=""),"",IF(R1004<>"",IF(R1004>P1004,"Traité hors délai","Non"),IF(Q1004="Classé sans suite","Non",IF(TODAY()>P1004,"OUI","Non"))))

Sheet Point hebdomadaire
A1: Point hebdomadaire des courriers arrivés
A3: Saisir une date de la semaine à analyser : | D3: 46286 | F3: INDICATEURS CLÉS DE LA SEMAINE
A4: Semaine n° | D4: =INT((D3-DATE(YEAR(D3-WEEKDAY(D3-1)+4),1,3)+WEEKDAY(DATE(YEAR(D3-WEEKDAY(D3-1)+4),1,3))+5)/7) -> 39 | F4: Courriers reçus | G4: =COUNTIFS(Registre!$B$5:$B$1004,">="&$D$5,Registre!$B$5:$B$1004,"<="&$D$6) -> 4
A5: Du (lundi) | D5: =D3-WEEKDAY(D3,2)+1 -> 46286 | F5: Courriers traités (toutes dates d'arrivée) | G5: =COUNTIFS(Registre!$R$5:$R$1004,">="&$D$5,Registre!$R$5:$R$1004,"<="&$D$6) -> 1
A6: Au (dimanche) | D6: =D5+6 -> 46292 | F6: dont reçus cette semaine | G6: =COUNTIFS(Registre!$B$5:$B$1004,">="&$D$5,Registre!$B$5:$B$1004,"<="&$D$6,Registre!$R$5:$R$1004,">="&$D$5,Registre!$R$5:$R$1004,"<="&$D$6) -> 0
A7: Situation arrêtée au | D7: =MIN(D6,TODAY()) -> 46292 | F7: Part des courriers de la semaine traités dans la semaine | G7: =IF(G4=0,0,G6/G4) -> 0
F8: Courriers en instance en fin de semaine | G8: =(COUNTIFS(Registre!$B$5:$B$1004,"<="&$D$7,Registre!$R$5:$R$1004,"",Registre!$Q$5:$Q$1004,"<>Classé sans suite")+COUNTIFS(Registre!$B$5:$B$1004,"<="&$D$7,Registre!$R$5:$R$1004,">"&$D$7)) -> 5
F9: dont en retard (date limite dépassée) | G9: =COUNTIFS(Registre!$B$5:$B$1004,"<="&$D$7,Registre!$R$5:$R$1004,"",Registre!$P$5:$P$1004,"<"&$D$7,Registre!$Q$5:$Q$1004,"<>Classé sans suite")+COUNTIFS(Registre!$B$5:$B$1004,"<="&$D$7,Registre!$R$5:$R$1004,">"&$D$7,Registre!$P$5:$P$1004,"<"&$D$7) -> 1
F10: Courriers très urgents / urgents reçus | G10: =COUNTIFS(Registre!$B$5:$B$1004,">="&$D$5,Registre!$B$5:$B$1004,"<="&$D$6,Registre!$L$5:$L$1004,"Très urgent")+COUNTIFS(Registre!$B$5:$B$1004,">="&$D$5,Registre!$B$5:$B$1004,"<="&$D$6,Registre!$L$5:$L$1004,"Urgent") -> 3
F11: Durée moyenne de traitement (jours) | G11: =IFERROR(AVERAGEIFS(Registre!$S$5:$S$1004,Registre!$R$5:$R$1004,">="&$D$5,Registre!$R$5:$R$1004,"<="&$D$6),0) -> 10
F12: Reçus la semaine précédente | G12: =COUNTIFS(Registre!$B$5:$B$1004,">="&($D$5-7),Registre!$B$5:$B$1004,"<="&($D$6-7)) -> 5
F13: Évolution vs semaine précédente | G13: =IF(G12=0,0,G4/G12-1) -> -0.2
A16: 1. Répartition par service imputé
A17: Élément | B17: Reçus | C17: Traités dans la semaine | D17: En instance fin de semaine | E17: dont en retard
A18: =IF(Paramètres!$A$5="","",Paramètres!$A$5) -> Cabinet du Ministre | B18: =IF($A18="","",COUNTIFS(Registre!$B$5:$B$1004,">="&$D$5,Registre!$B$5:$B$1004,"<="&$D$6,Registre!$M$5:$M$1004,$A18)) -> 0 | C18: =IF($A18="","",COUNTIFS(Registre!$M$5:$M$1004,$A18,Registre!$R$5:$R$1004,">="&$D$5,Registre!$R$5:$R$1004,"<="&$D$6)) -> 0 | D18: =IF($A18="","",COUNTIFS(Registre!$M$5:$M$1004,$A18,Registre!$B$5:$B$1004,"<="&$D$7,Registre!$R$5:$R$1004,"",Registre!$Q$5:$Q$1004,"<>Classé sans suite")+COUNTIFS(Registre!$M$5:$M$1004,$A18,Registre!$B$5:$B$1004,"<="&$D$7,Registre!$R$5:$R$1004,">"&$D$7)) -> 0 | E18: =IF($A18="","",COUNTIFS(Registre!$M$5:$M$1004,$A18,Registre!$B$5:$B$1004,"<="&$D$7,Registre!$R$5:$R$1004,"",Registre!$P$5:$P$1004,"<"&$D$7,Registre!$Q$5:$Q$1004,"<>Classé sans suite")+COUNTIFS(Registre!$M$5:$M$1004,$A18,Registre!$B$5:$B$1004,"<="&$D$7,Registre!$R$5:$R$1004,">"&$D$7,Registre!$P$5:$P$1004,"<"&$D$7)) -> 0
A19: =IF(Paramètres!$A$6="","",Paramètres!$A$6) -> Secrétariat Général | B19: =IF($A19="","",COUNTIFS(Registre!$B$5:$B$1004,">="&$D$5,Registre!$B$5:$B$1004,"<="&$D$6,Registre!$M$5:$M$1004,$A19)) -> 1 | C19: =IF($A19="","",COUNTIFS(Registre!$M$5:$M$1004,$A19,Registre!$R$5:$R$1004,">="&$D$5,Registre!$R$5:$R$1004,"<="&$D$6)) -> 0 | D19: =IF($A19="","",COUNTIFS(Registre!$M$5:$M$1004,$A19,Registre!$B$5:$B$1004,"<="&$D$7,Registre!$R$5:$R$1004,"",Registre!$Q$5:$Q$1004,"<>Classé sans suite")+COUNTIFS(Registre!$M$5:$M$1004,$A19,Registre!$B$5:$B$1004,"<="&$D$7,Registre!$R$5:$R$1004,">"&$D$7)) -> 1 | E19: =IF($A19="","",COUNTIFS(Registre!$M$5:$M$1004,$A19,Registre!$B$5:$B$1004,"<="&$D$7,Registre!$R$5:$R$1004,"",Registre!$P$5:$P$1004,"<"&$D$7,Registre!$Q$5:$Q$1004,"<>Classé sans suite")+COUNTIFS(Registre!$M$5:$M$1004,$A19,Registre!$B$5:$B$1004,"<="&$D$7,Registre!$R$5:$R$1004,">"&$D$7,Registre!$P$5:$P$1004,"<"&$D$7)) -> 1
A20: =IF(Paramètres!$A$7="","",Paramètres!$A$7) -> Direction des Affaires Administratives et Financières | B20: =IF($A20="","",COUNTIFS(Registre!$B$5:$B$1004,">="&$D$5,Registre!$B$5:$B$1004,"<="&$D$6,Registre!$M$5:$M$1004,$A20)) -> 0 | C20: =IF($A20="","",COUNTIFS(Registre!$M$5:$M$1004,$A20,Registre!$R$5:$R$1004,">="&$D$5,Registre!$R$5:$R$1004,"<="&$D$6)) -> 0 | D20: =IF($A20="","",COUNTIFS(Registre!$M$5:$M$1004,$A20,Registre!$B$5:$B$1004,"<="&$D$7,Registre!$R$5:$R$1004,"",Registre!$Q$5:$Q$1004,"<>Classé sans suite")+COUNTIFS(Registre!$M$5:$M$1004,$A20,Registre!$B$5:$B$1004,"<="&$D$7,Registre!$R$5:$R$1004,">"&$D$7)) -> 1 | E20: =IF($A20="","",COUNTIFS(Registre!$M$5:$M$1004,$A20,Registre!$B$5:$B$1004,"<="&$D$7,Registre!$R$5:$R$1004,"",Registre!$P$5:$P$1004,"<"&$D$7,Registre!$Q$5:$Q$1004,"<>Classé sans suite")+COUNTIFS(Registre!$M$5:$M$1004,$A20,Registre!$B$5:$B$1004,"<="&$D$7,Registre!$R$5:$R$1004,">"&$D$7,Registre!$P$5:$P$1004,"<"&$D$7)) -> 0
A21: =IF(Paramètres!$A$8="","",Paramètres!$A$8) -> Direction des Ressources Humaines | B21: =IF($A21="","",COUNTIFS(Registre!$B$5:$B$1004,">="&$D$5,Registre!$B$5:$B$1004,"<="&$D$6,Registre!$M$5:$M$1004,$A21)) -> 0 | C21: =IF($A21="","",COUNTIFS(Registre!$M$5:$M$1004,$A21,Registre!$R$5:$R$1004,">="&$D$5,Registre!$R$5:$R$1004,"<="&$D$6)) -> 1 | D21: =IF($A21="","",COUNTIFS(Registre!$M$5:$M$1004,$A21,Registre!$B$5:$B$1004,"<="&$D$7,Registre!$R$5:$R$1004,"",Registre!$Q$5:$Q$1004,"<>Classé sans suite")+COUNTIFS(Registre!$M$5:$M$1004,$A21,Registre!$B$5:$B$1004,"<="&$D$7,Registre!$R$5:$R$1004,">"&$D$7)) -> 0 | E21: =IF($A21="","",COUNTIFS(Registre!$M$5:$M$1004,$A21,Registre!$B$5:$B$1004,"<="&$D$7,Registre!$R$5:$R$1004,"",Registre!$P$5:$P$1004,"<"&$D$7,Registre!$Q$5:$Q$1004,"<>Classé sans suite")+COUNTIFS(Registre!$M$5:$M$1004,$A21,Registre!$B$5:$B$1004,"<="&$D$7,Registre!$R$5:$R$1004,">"&$D$7,Registre!$P$5:$P$1004,"<"&$D$7)) -> 0
A22: =IF(Paramètres!$A$9="","",Paramètres!$A$9) -> Direction de la Planification et des Études | B22: =IF($A22="","",COUNTIFS(Registre!$B$5:$B$1004,">="&$D$5,Registre!$B$5:$B$1004,"<="&$D$6,Registre!$M$5:$M$1004,$A22)) -> 0 | C22: =IF($A22="","",COUNTIFS(Registre!$M$5:$M$1004,$A22,Registre!$R$5:$R$1004,">="&$D$5,Registre!$R$5:$R$1004,"<="&$D$6)) -> 0 | D22: =IF($A22="","",COUNTIFS(Registre!$M$5:$M$1004,$A22,Registre!$B$5:$B$1004,"<="&$D$7,Registre!$R$5:$R$1004,"",Registre!$Q$5:$Q$1004,"<>Classé sans suite")+COUNTIFS(Registre!$M$5:$M$1004,$A22,Registre!$B$5:$B$1004,"<="&$D$7,Registre!$R$5:$R$1004,">"&$D$7)) -> 1 | E22: =IF($A22="","",COUNTIFS(Registre!$M$5:$M$1004,$A22,Registre!$B$5:$B$1004,"<="&$D$7,Registre!$R$5:$R$1004,"",Registre!$P$5:$P$1004,"<"&$D$7,Registre!$Q$5:$Q$1004,"<>Classé sans suite")+COUNTIFS(Registre!$M$5:$M$1004,$A22,Registre!$B$5:$B$1004,"<="&$D$7,Registre!$R$5:$R$1004,">"&$D$7,Registre!$P$5:$P$1004,"<"&$D$7)) -> 0
A23: =IF(Paramètres!$A$10="","",Paramètres!$A$10) -> Direction des Affaires Juridiques | B23: =IF($A23="","",COUNTIFS(Registre!$B$5:$B$1004,">="&$D$5,Registre!$B$5:$B$1004,"<="&$D$6,Registre!$M$5:$M$1004,$A23)) -> 1 | C23: =IF($A23="","",COUNTIFS(Registre!$M$5:$M$1004,$A23,Registre!$R$5:$R$1004,">="&$D$5,Registre!$R$5:$R$1004,"<="&$D$6)) -> 0 | D23: =IF($A23="","",COUNTIFS(Registre!$M$5:$M$1004,$A23,Registre!$B$5:$B$1004,"<="&$D$7,Registre!$R$5:$R$1004,"",Registre!$Q$5:$Q$1004,"<>Classé sans suite")+COUNTIFS(Registre!$M$5:$M$1004,$A23,Registre!$B$5:$B$1004,"<="&$D$7,Registre!$R$5:$R$1004,">"&$D$7)) -> 1 | E23: =IF($A23="","",COUNTIFS(Registre!$M$5:$M$1004,$A23,Registre!$B$5:$B$1004,"<="&$D$7,Registre!$R$5:$R$1004,"",Registre!$P$5:$P$1004,"<"&$D$7,Registre!$Q$5:$Q$1004,"<>Classé sans suite")+COUNTIFS(Registre!$M$5:$M$1004,$A23,Registre!$B$5:$B$1004,"<="&$D$7,Registre!$R$5:$R$1004,">"&$D$7,Registre!$P$5:$P$1004,"<"&$D$7)) -> 0
A24: =IF(Paramètres!$A$11="","",Paramètres!$A$11) -> Direction de la Communication | B24: =IF($A24="","",COUNTIFS(Registre!$B$5:$B$1004,">="&$D$5,Registre!$B$5:$B$1004,"<="&$D$6,Registre!$M$5:$M$1004,$A24)) -> 1 | C24: =IF($A24="","",COUNTIFS(Registre!$M$5:$M$1004,$A24,Registre!$R$5:$R$1004,">="&$D$5,Registre!$R$5:$R$1004,"<="&$D$6)) -> 0 | D24: =IF($A24="","",COUNTIFS(Registre!$M$5:$M$1004,$A24,Registre!$B$5:$B$1004,"<="&$D$7,Registre!$R$5:$R$1004,"",Registre!$Q$5:$Q$1004,"<>Classé sans suite")+COUNTIFS(Registre!$M$5:$M$1004,$A24,Registre!$B$5:$B$1004,"<="&$D$7,Registre!$R$5:$R$1004,">"&$D$7)) -> 0 | E24: =IF($A24="","",COUNTIFS(Registre!$M$5:$M$1004,$A24,Registre!$B$5:$B$1004,"<="&$D$7,Registre!$R$5:$R$1004,"",Registre!$P$5:$P$1004,"<"&$D$7,Registre!$Q$5:$Q$1004,"<>Classé sans suite")+COUNTIFS(Registre!$M$5:$M$1004,$A24,Registre!$B$5:$B$1004,"<="&$D$7,Registre!$R$5:$R$1004,">"&$D$7,Registre!$P$5:$P$1004,"<"&$D$7)) -> 0
A25: =IF(Paramètres!$A$12="","",Paramètres!$A$12) -> Inspection Générale | B25: =IF($A25="","",COUNTIFS(Registre!$B$5:$B$1004,">="&$D$5,Registre!$B$5:$B$1004,"<="&$D$6,Registre!$M$5:$M$1004,$A25)) -> 1 | C25: =IF($A25="","",COUNTIFS(Registre!$M$5:$M$1004,$A25,Registre!$R$5:$R$1004,">="&$D$5,Registre!$R$5:$R$1004,"<="&$D$6)) -> 0 | D25: =IF($A25="","",COUNTIFS(Registre!$M$5:$M$1004,$A25,Registre!$B$5:$B$1004,"<="&$D$7,Registre!$R$5:$R$1004,"",Registre!$Q$5:$Q$1004,"<>Classé sans suite")+COUNTIFS(Registre!$M$5:$M$1004,$A25,Registre!$B$5:$B$1004,"<="&$D$7,Registre!$R$5:$R$1004,">"&$D$7)) -> 1 | E25: =IF($A25="","",COUNTIFS(Registre!$M$5:$M$1004,$A25,Registre!$B$5:$B$1004,"<="&$D$7,Registre!$R$5:$R$1004,"",Registre!$P$5:$P$1004,"<"&$D$7,Registre!$Q$5:$Q$1004,"<>Classé sans suite")+COUNTIFS(Registre!$M$5:$M$1004,$A25,Registre!$B$5:$B$1004,"<="&$D$7,Registre!$R$5:$R$1004,">"&$D$7,Registre!$P$5:$P$1004,"<"&$D$7)) -> 0
A26: =IF(Paramètres!$A$13="","",Paramètres!$A$13) | B26: =IF($A26="","",COUNTIFS(Registre!$B$5:$B$1004,">="&$D$5,Registre!$B$5:$B$1004,"<="&$D$6,Registre!$M$5:$M$1004,$A26)) | C26: =IF($A26="","",COUNTIFS(Registre!$M$5:$M$1004,$A26,Registre!$R$5:$R$1004,">="&$D$5,Registre!$R$5:$R$1004,"<="&$D$6)) | D26: =IF($A26="","",COUNTIFS(Registre!$M$5:$M$1004,$A26,Registre!$B$5:$B$1004,"<="&$D$7,Registre!$R$5:$R$1004,"",Registre!$Q$5:$Q$1004,"<>Classé sans suite")+COUNTIFS(Registre!$M$5:$M$1004,$A26,Registre!$B$5:$B$1004,"<="&$D$7,Registre!$R$5:$R$1004,">"&$D$7)) | E26: =IF($A26="","",COUNTIFS(Registre!$M$5:$M$1004,$A26,Registre!$B$5:$B$1004,"<="&$D$7,Registre!$R$5:$R$1004,"",Registre!$P$5:$P$1004,"<"&$D$7,Registre!$Q$5:$Q$1004,"<>Classé sans suite")+COUNTIFS(Registre!$M$5:$M$1004,$A26,Registre!$B$5:$B$1004,"<="&$D$7,Registre!$R$5:$R$1004,">"&$D$7,Registre!$P$5:$P$1004,"<"&$D$7))
A27: =IF(Paramètres!$A$14="","",Paramètres!$A$14) | B27: =IF($A27="","",COUNTIFS(Registre!$B$5:$B$1004,">="&$D$5,Registre!$B$5:$B$1004,"<="&$D$6,Registre!$M$5:$M$1004,$A27)) | C27: =IF($A27="","",COUNTIFS(Registre!$M$5:$M$1004,$A27,Registre!$R$5:$R$1004,">="&$D$5,Registre!$R$5:$R$1004,"<="&$D$6)) | D27: =IF($A27="","",COUNTIFS(Registre!$M$5:$M$1004,$A27,Registre!$B$5:$B$1004,"<="&$D$7,Registre!$R$5:$R$1004,"",Registre!$Q$5:$Q$1004,"<>Classé sans suite")+COUNTIFS(Registre!$M$5:$M$1004,$A27,Registre!$B$5:$B$1004,"<="&$D$7,Registre!$R$5:$R$1004,">"&$D$7)) | E27: =IF($A27="","",COUNTIFS(Registre!$M$5:$M$1004,$A27,Registre!$B$5:$B$1004,"<="&$D$7,Registre!$R$5:$R$1004,"",Registre!$P$5:$P$1004,"<"&$D$7,Registre!$Q$5:$Q$1004,"<>Classé sans suite")+COUNTIFS(Registre!$M$5:$M$1004,$A27,Registre!$B$5:$B$1004,"<="&$D$7,Registre!$R$5:$R$1004,">"&$D$7,Registre!$P$5:$P$1004,"<"&$D$7))
A28: =IF(Paramètres!$A$15="","",Paramètres!$A$15) | B28: =IF($A28="","",COUNTIFS(Registre!$B$5:$B$1004,">="&$D$5,Registre!$B$5:$B$1004,"<="&$D$6,Registre!$M$5:$M$1004,$A28)) | C28: =IF($A28="","",COUNTIFS(Registre!$M$5:$M$1004,$A28,Registre!$R$5:$R$1004,">="&$D$5,Registre!$R$5:$R$1004,"<="&$D$6)) | D28: =IF($A28="","",COUNTIFS(Registre!$M$5:$M$1004,$A28,Registre!$B$5:$B$1004,"<="&$D$7,Registre!$R$5:$R$1004,"",Registre!$Q$5:$Q$1004,"<>Classé sans suite")+COUNTIFS(Registre!$M$5:$M$1004,$A28,Registre!$B$5:$B$1004,"<="&$D$7,Registre!$R$5:$R$1004,">"&$D$7)) | E28: =IF($A28="","",COUNTIFS(Registre!$M$5:$M$1004,$A28,Registre!$B$5:$B$1004,"<="&$D$7,Registre!$R$5:$R$1004,"",Registre!$P$5:$P$1004,"<"&$D$7,Registre!$Q$5:$Q$1004,"<>Classé sans suite")+COUNTIFS(Registre!$M$5:$M$1004,$A28,Registre!$B$5:$B$1004,"<="&$D$7,Registre!$R$5:$R$1004,">"&$D$7,Registre!$P$5:$P$1004,"<"&$D$7))
A29: =IF(Paramètres!$A$16="","",Paramètres!$A$16) | B29: =IF($A29="","",COUNTIFS(Registre!$B$5:$B$1004,">="&$D$5,Registre!$B$5:$B$1004,"<="&$D$6,Registre!$M$5:$M$1004,$A29)) | C29: =IF($A29="","",COUNTIFS(Registre!$M$5:$M$1004,$A29,Registre!$R$5:$R$1004,">="&$D$5,Registre!$R$5:$R$1004,"<="&$D$6)) | D29: =IF($A29="","",COUNTIFS(Registre!$M$5:$M$1004,$A29,Registre!$B$5:$B$1004,"<="&$D$7,Registre!$R$5:$R$1004,"",Registre!$Q$5:$Q$1004,"<>Classé sans suite")+COUNTIFS(Registre!$M$5:$M$1004,$A29,Registre!$B$5:$B$1004,"<="&$D$7,Registre!$R$5:$R$1004,">"&$D$7)) | E29: =IF($A29="","",COUNTIFS(Registre!$M$5:$M$1004,$A29,Registre!$B$5:$B$1004,"<="&$D$7,Registre!$R$5:$R$1004,"",Registre!$P$5:$P$1004,"<"&$D$7,Registre!$Q$5:$Q$1004,"<>Classé sans suite")+COUNTIFS(Registre!$M$5:$M$1004,$A29,Registre!$B$5:$B$1004,"<="&$D$7,Registre!$R$5:$R$1004,">"&$D$7,Registre!$P$5:$P$1004,"<"&$D$7))
A30: TOTAL | B30: =SUM(B18:B29) -> 4 | C30: =SUM(C18:C29) -> 1 | D30: =SUM(D18:D29) -> 5 | E30: =SUM(E18:E29) -> 1
A31: Courriers reçus non encore imputés | B31: =COUNTIFS(Registre!$B$5:$B$1004,">="&$D$5,Registre!$B$5:$B$1004,"<="&$D$6,Registre!$M$5:$M$1004,"") -> 0
A33: 2. Répartition par type de courrier
A34: Élément | B34: Reçus | C34: Part (%)
A35: =IF(Paramètres!$B$5="","",Paramètres!$B$5) -> Lettre | B35: =IF($A35="","",COUNTIFS(Registre!$B$5:$B$1004,">="&$D$5,Registre!$B$5:$B$1004,"<="&$D$6,Registre!$J$5:$J$1004,$A35)) -> 0 | C35: =IF($A35="","",IF($B$45=0,0,COUNTIFS(Registre!$B$5:$B$1004,">="&$D$5,Registre!$B$5:$B$1004,"<="&$D$6,Registre!$J$5:$J$1004,$A35)/$B$45)) -> 0
A36: =IF(Paramètres!$B$6="","",Paramètres!$B$6) -> Note de service | B36: =IF($A36="","",COUNTIFS(Registre!$B$5:$B$1004,">="&$D$5,Registre!$B$5:$B$1004,"<="&$D$6,Registre!$J$5:$J$1004,$A36)) -> 0 | C36: =IF($A36="","",IF($B$45=0,0,COUNTIFS(Registre!$B$5:$B$1004,">="&$D$5,Registre!$B$5:$B$1004,"<="&$D$6,Registre!$J$5:$J$1004,$A36)/$B$45)) -> 0
A37: =IF(Paramètres!$B$7="","",Paramètres!$B$7) -> Demande | B37: =IF($A37="","",COUNTIFS(Registre!$B$5:$B$1004,">="&$D$5,Registre!$B$5:$B$1004,"<="&$D$6,Registre!$J$5:$J$1004,$A37)) -> 1 | C37: =IF($A37="","",IF($B$45=0,0,COUNTIFS(Registre!$B$5:$B$1004,">="&$D$5,Registre!$B$5:$B$1004,"<="&$D$6,Registre!$J$5:$J$1004,$A37)/$B$45)) -> 0.25
A38: =IF(Paramètres!$B$8="","",Paramètres!$B$8) -> Réclamation | B38: =IF($A38="","",COUNTIFS(Registre!$B$5:$B$1004,">="&$D$5,Registre!$B$5:$B$1004,"<="&$D$6,Registre!$J$5:$J$1004,$A38)) -> 1 | C38: =IF($A38="","",IF($B$45=0,0,COUNTIFS(Registre!$B$5:$B$1004,">="&$D$5,Registre!$B$5:$B$1004,"<="&$D$6,Registre!$J$5:$J$1004,$A38)/$B$45)) -> 0.25
A39: =IF(Paramètres!$B$9="","",Paramètres!$B$9) -> Invitation | B39: =IF($A39="","",COUNTIFS(Registre!$B$5:$B$1004,">="&$D$5,Registre!$B$5:$B$1004,"<="&$D$6,Registre!$J$5:$J$1004,$A39)) -> 1 | C39: =IF($A39="","",IF($B$45=0,0,COUNTIFS(Registre!$B$5:$B$1004,">="&$D$5,Registre!$B$5:$B$1004,"<="&$D$6,Registre!$J$5:$J$1004,$A39)/$B$45)) -> 0.25
A40: =IF(Paramètres!$B$10="","",Paramètres!$B$10) -> Rapport | B40: =IF($A40="","",COUNTIFS(Registre!$B$5:$B$1004,">="&$D$5,Registre!$B$5:$B$1004,"<="&$D$6,Registre!$J$5:$J$1004,$A40)) -> 0 | C40: =IF($A40="","",IF($B$45=0,0,COUNTIFS(Registre!$B$5:$B$1004,">="&$D$5,Registre!$B$5:$B$1004,"<="&$D$6,Registre!$J$5:$J$1004,$A40)/$B$45)) -> 0
A41: =IF(Paramètres!$B$11="","",Paramètres!$B$11) -> Facture | B41: =IF($A41="","",COUNTIFS(Registre!$B$5:$B$1004,">="&$D$5,Registre!$B$5:$B$1004,"<="&$D$6,Registre!$J$5:$J$1004,$A41)) -> 0 | C41: =IF($A41="","",IF($B$45=0,0,COUNTIFS(Registre!$B$5:$B$1004,">="&$D$5,Registre!$B$5:$B$1004,"<="&$D$6,Registre!$J$5:$J$1004,$A41)/$B$45)) -> 0
A42: =IF(Paramètres!$B$12="","",Paramètres!$B$12) -> Convocation | B42: =IF($A42="","",COUNTIFS(Registre!$B$5:$B$1004,">="&$D$5,Registre!$B$5:$B$1004,"<="&$D$6,Registre!$J$5:$J$1004,$A42)) -> 0 | C42: =IF($A42="","",IF($B$45=0,0,COUNTIFS(Registre!$B$5:$B$1004,">="&$D$5,Registre!$B$5:$B$1004,"<="&$D$6,Registre!$J$5:$J$1004,$A42)/$B$45)) -> 0
A43: =IF(Paramètres!$B$13="","",Paramètres!$B$13) -> Circulaire | B43: =IF($A43="","",COUNTIFS(Registre!$B$5:$B$1004,">="&$D$5,Registre!$B$5:$B$1004,"<="&$D$6,Registre!$J$5:$J$1004,$A43)) -> 1 | C43: =IF($A43="","",IF($B$45=0,0,COUNTIFS(Registre!$B$5:$B$1004,">="&$D$5,Registre!$B$5:$B$1004,"<="&$D$6,Registre!$J$5:$J$1004,$A43)/$B$45)) -> 0.25
A44: =IF(Paramètres!$B$14="","",Paramètres!$B$14) -> Autre | B44: =IF($A44="","",COUNTIFS(Registre!$B$5:$B$1004,">="&$D$5,Registre!$B$5:$B$1004,"<="&$D$6,Registre!$J$5:$J$1004,$A44)) -> 0 | C44: =IF($A44="","",IF($B$45=0,0,COUNTIFS(Registre!$B$5:$B$1004,">="&$D$5,Registre!$B$5:$B$1004,"<="&$D$6,Registre!$J$5:$J$1004,$A44)/$B$45)) -> 0
...

Sheet Synthèse annuelle
A1: Synthèse hebdomadaire sur l'année
A2: ="Année "&Paramètres!$G$12&" (modifiable dans l'onglet Paramètres) – semaines ISO du lundi au dimanche" -> Année 2026 (modifiable dans l'onglet Paramètres) – semaines ISO du lundi au dimanche
A4: Semaine n° | B4: Du | C4: Au | D4: Reçus | E4: Traités | F4: Urgents / très urgents reçus | G4: En instance fin de semaine | H4: dont en retard | I4: Part des reçus déjà traités
A5: 1 | B5: =DATE(Paramètres!$G$12,1,4)-WEEKDAY(DATE(Paramètres!$G$12,1,4),2)+1+7*(A5-1) -> 46020 | C5: =B5+6 -> 46026 | D5: =COUNTIFS(Registre!$B$5:$B$1004,">="&$B5,Registre!$B$5:$B$1004,"<="&$C5) -> 0 | E5: =COUNTIFS(Registre!$R$5:$R$1004,">="&$B5,Registre!$R$5:$R$1004,"<="&$C5) -> 0 | F5: =COUNTIFS(Registre!$B$5:$B$1004,">="&$B5,Registre!$B$5:$B$1004,"<="&$C5,Registre!$L$5:$L$1004,"Très urgent")+COUNTIFS(Registre!$B$5:$B$1004,">="&$B5,Registre!$B$5:$B$1004,"<="&$C5,Registre!$L$5:$L$1004,"Urgent") -> 0 | G5: =IF($B5>TODAY(),"",COUNTIFS(Registre!$B$5:$B$1004,"<="&MIN($C5,TODAY()),Registre!$R$5:$R$1004,"",Registre!$Q$5:$Q$1004,"<>Classé sans suite")+COUNTIFS(Registre!$B$5:$B$1004,"<="&MIN($C5,TODAY()),Registre!$R$5:$R$1004,">"&MIN($C5,TODAY()))) -> 0 | H5: =IF($B5>TODAY(),"",COUNTIFS(Registre!$B$5:$B$1004,"<="&MIN($C5,TODAY()),Registre!$R$5:$R$1004,"",Registre!$P$5:$P$1004,"<"&MIN($C5,TODAY()),Registre!$Q$5:$Q$1004,"<>Classé sans suite")+COUNTIFS(Registre!$B$5:$B$1004,"<="&MIN($C5,TODAY()),Registre!$R$5:$R$1004,">"&MIN($C5,TODAY()),Registre!$P$5:$P$1004,"<"&MIN($C5,TODAY()))) -> 0 | I5: =IF(D5=0,"",COUNTIFS(Registre!$B$5:$B$1004,">="&$B5,Registre!$B$5:$B$1004,"<="&$C5,Registre!$R$5:$R$1004,"<>")/D5)
A6: 2 | B6: =DATE(Paramètres!$G$12,1,4)-WEEKDAY(DATE(Paramètres!$G$12,1,4),2)+1+7*(A6-1) -> 46027 | C6: =B6+6 -> 46033 | D6: =COUNTIFS(Registre!$B$5:$B$1004,">="&$B6,Registre!$B$5:$B$1004,"<="&$C6) -> 0 | E6: =COUNTIFS(Registre!$R$5:$R$1004,">="&$B6,Registre!$R$5:$R$1004,"<="&$C6) -> 0 | F6: =COUNTIFS(Registre!$B$5:$B$1004,">="&$B6,Registre!$B$5:$B$1004,"<="&$C6,Registre!$L$5:$L$1004,"Très urgent")+COUNTIFS(Registre!$B$5:$B$1004,">="&$B6,Registre!$B$5:$B$1004,"<="&$C6,Registre!$L$5:$L$1004,"Urgent") -> 0 | G6: =IF($B6>TODAY(),"",COUNTIFS(Registre!$B$5:$B$1004,"<="&MIN($C6,TODAY()),Registre!$R$5:$R$1004,"",Registre!$Q$5:$Q$1004,"<>Classé sans suite")+COUNTIFS(Registre!$B$5:$B$1004,"<="&MIN($C6,TODAY()),Registre!$R$5:$R$1004,">"&MIN($C6,TODAY()))) -> 0 | H6: =IF($B6>TODAY(),"",COUNTIFS(Registre!$B$5:$B$1004,"<="&MIN($C6,TODAY()),Registre!$R$5:$R$1004,"",Registre!$P$5:$P$1004,"<"&MIN($C6,TODAY()),Registre!$Q$5:$Q$1004,"<>Classé sans suite")+COUNTIFS(Registre!$B$5:$B$1004,"<="&MIN($C6,TODAY()),Registre!$R$5:$R$1004,">"&MIN($C6,TODAY()),Registre!$P$5:$P$1004,"<"&MIN($C6,TODAY()))) -> 0 | I6: =IF(D6=0,"",COUNTIFS(Registre!$B$5:$B$1004,">="&$B6,Registre!$B$5:$B$1004,"<="&$C6,Registre!$R$5:$R$1004,"<>")/D6)
A7: 3 | B7: =DATE(Paramètres!$G$12,1,4)-WEEKDAY(DATE(Paramètres!$G$12,1,4),2)+1+7*(A7-1) -> 46034 | C7: =B7+6 -> 46040 | D7: =COUNTIFS(Registre!$B$5:$B$1004,">="&$B7,Registre!$B$5:$B$1004,"<="&$C7) -> 0 | E7: =COUNTIFS(Registre!$R$5:$R$1004,">="&$B7,Registre!$R$5:$R$1004,"<="&$C7) -> 0 | F7: =COUNTIFS(Registre!$B$5:$B$1004,">="&$B7,Registre!$B$5:$B$1004,"<="&$C7,Registre!$L$5:$L$1004,"Très urgent")+COUNTIFS(Registre!$B$5:$B$1004,">="&$B7,Registre!$B$5:$B$1004,"<="&$C7,Registre!$L$5:$L$1004,"Urgent") -> 0 | G7: =IF($B7>TODAY(),"",COUNTIFS(Registre!$B$5:$B$1004,"<="&MIN($C7,TODAY()),Registre!$R$5:$R$1004,"",Registre!$Q$5:$Q$1004,"<>Classé sans suite")+COUNTIFS(Registre!$B$5:$B$1004,"<="&MIN($C7,TODAY()),Registre!$R$5:$R$1004,">"&MIN($C7,TODAY()))) -> 0 | H7: =IF($B7>TODAY(),"",COUNTIFS(Registre!$B$5:$B$1004,"<="&MIN($C7,TODAY()),Registre!$R$5:$R$1004,"",Registre!$P$5:$P$1004,"<"&MIN($C7,TODAY()),Registre!$Q$5:$Q$1004,"<>Classé sans suite")+COUNTIFS(Registre!$B$5:$B$1004,"<="&MIN($C7,TODAY()),Registre!$R$5:$R$1004,">"&MIN($C7,TODAY()),Registre!$P$5:$P$1004,"<"&MIN($C7,TODAY()))) -> 0 | I7: =IF(D7=0,"",COUNTIFS(Registre!$B$5:$B$1004,">="&$B7,Registre!$B$5:$B$1004,"<="&$C7,Registre!$R$5:$R$1004,"<>")/D7)
A8: 4 | B8: =DATE(Paramètres!$G$12,1,4)-WEEKDAY(DATE(Paramètres!$G$12,1,4),2)+1+7*(A8-1) -> 46041 | C8: =B8+6 -> 46047 | D8: =COUNTIFS(Registre!$B$5:$B$1004,">="&$B8,Registre!$B$5:$B$1004,"<="&$C8) -> 0 | E8: =COUNTIFS(Registre!$R$5:$R$1004,">="&$B8,Registre!$R$5:$R$1004,"<="&$C8) -> 0 | F8: =COUNTIFS(Registre!$B$5:$B$1004,">="&$B8,Registre!$B$5:$B$1004,"<="&$C8,Registre!$L$5:$L$1004,"Très urgent")+COUNTIFS(Registre!$B$5:$B$1004,">="&$B8,Registre!$B$5:$B$1004,"<="&$C8,Registre!$L$5:$L$1004,"Urgent") -> 0 | G8: =IF($B8>TODAY(),"",COUNTIFS(Registre!$B$5:$B$1004,"<="&MIN($C8,TODAY()),Registre!$R$5:$R$1004,"",Registre!$Q$5:$Q$1004,"<>Classé sans suite")+COUNTIFS(Registre!$B$5:$B$1004,"<="&MIN($C8,TODAY()),Registre!$R$5:$R$1004,">"&MIN($C8,TODAY()))) -> 0 | H8: =IF($B8>TODAY(),"",COUNTIFS(Registre!$B$5:$B$1004,"<="&MIN($C8,TODAY()),Registre!$R$5:$R$1004,"",Registre!$P$5:$P$1004,"<"&MIN($C8,TODAY()),Registre!$Q$5:$Q$1004,"<>Classé sans suite")+COUNTIFS(Registre!$B$5:$B$1004,"<="&MIN($C8,TODAY()),Registre!$R$5:$R$1004,">"&MIN($C8,TODAY()),Registre!$P$5:$P$1004,"<"&MIN($C8,TODAY()))) -> 0 | I8: =IF(D8=0,"",COUNTIFS(Registre!$B$5:$B$1004,">="&$B8,Registre!$B$5:$B$1004,"<="&$C8,Registre!$R$5:$R$1004,"<>")/D8)
A9: 5 | B9: =DATE(Paramètres!$G$12,1,4)-WEEKDAY(DATE(Paramètres!$G$12,1,4),2)+1+7*(A9-1) -> 46048 | C9: =B9+6 -> 46054 | D9: =COUNTIFS(Registre!$B$5:$B$1004,">="&$B9,Registre!$B$5:$B$1004,"<="&$C9) -> 0 | E9: =COUNTIFS(Registre!$R$5:$R$1004,">="&$B9,Registre!$R$5:$R$1004,"<="&$C9) -> 0 | F9: =COUNTIFS(Registre!$B$5:$B$1004,">="&$B9,Registre!$B$5:$B$1004,"<="&$C9,Registre!$L$5:$L$1004,"Très urgent")+COUNTIFS(Registre!$B$5:$B$1004,">="&$B9,Registre!$B$5:$B$1004,"<="&$C9,Registre!$L$5:$L$1004,"Urgent") -> 0 | G9: =IF($B9>TODAY(),"",COUNTIFS(Registre!$B$5:$B$1004,"<="&MIN($C9,TODAY()),Registre!$R$5:$R$1004,"",Registre!$Q$5:$Q$1004,"<>Classé sans suite")+COUNTIFS(Registre!$B$5:$B$1004,"<="&MIN($C9,TODAY()),Registre!$R$5:$R$1004,">"&MIN($C9,TODAY()))) -> 0 | H9: =IF($B9>TODAY(),"",COUNTIFS(Registre!$B$5:$B$1004,"<="&MIN($C9,TODAY()),Registre!$R$5:$R$1004,"",Registre!$P$5:$P$1004,"<"&MIN($C9,TODAY()),Registre!$Q$5:$Q$1004,"<>Classé sans suite")+COUNTIFS(Registre!$B$5:$B$1004,"<="&MIN($C9,TODAY()),Registre!$R$5:$R$1004,">"&MIN($C9,TODAY()),Registre!$P$5:$P$1004,"<"&MIN($C9,TODAY()))) -> 0 | I9: =IF(D9=0,"",COUNTIFS(Registre!$B$5:$B$1004,">="&$B9,Registre!$B$5:$B$1004,"<="&$C9,Registre!$R$5:$R$1004,"<>")/D9)
A10: 6 | B10: =DATE(Paramètres!$G$12,1,4)-WEEKDAY(DATE(Paramètres!$G$12,1,4),2)+1+7*(A10-1) -> 46055 | C10: =B10+6 -> 46061 | D10: =COUNTIFS(Registre!$B$5:$B$1004,">="&$B10,Registre!$B$5:$B$1004,"<="&$C10) -> 0 | E10: =COUNTIFS(Registre!$R$5:$R$1004,">="&$B10,Registre!$R$5:$R$1004,"<="&$C10) -> 0 | F10: =COUNTIFS(Registre!$B$5:$B$1004,">="&$B10,Registre!$B$5:$B$1004,"<="&$C10,Registre!$L$5:$L$1004,"Très urgent")+COUNTIFS(Registre!$B$5:$B$1004,">="&$B10,Registre!$B$5:$B$1004,"<="&$C10,Registre!$L$5:$L$1004,"Urgent") -> 0 | G10: =IF($B10>TODAY(),"",COUNTIFS(Registre!$B$5:$B$1004,"<="&MIN($C10,TODAY()),Registre!$R$5:$R$1004,"",Registre!$Q$5:$Q$1004,"<>Classé sans suite")+COUNTIFS(Registre!$B$5:$B$1004,"<="&MIN($C10,TODAY()),Registre!$R$5:$R$1004,">"&MIN($C10,TODAY()))) -> 0 | H10: =IF($B10>TODAY(),"",COUNTIFS(Registre!$B$5:$B$1004,"<="&MIN($C10,TODAY()),Registre!$R$5:$R$1004,"",Registre!$P$5:$P$1004,"<"&MIN($C10,TODAY()),Registre!$Q$5:$Q$1004,"<>Classé sans suite")+COUNTIFS(Registre!$B$5:$B$1004,"<="&MIN($C10,TODAY()),Registre!$R$5:$R$1004,">"&MIN($C10,TODAY()),Registre!$P$5:$P$1004,"<"&MIN($C10,TODAY()))) -> 0 | I10: =IF(D10=0,"",COUNTIFS(Registre!$B$5:$B$1004,">="&$B10,Registre!$B$5:$B$1004,"<="&$C10,Registre!$R$5:$R$1004,"<>")/D10)
A11: 7 | B11: =DATE(Paramètres!$G$12,1,4)-WEEKDAY(DATE(Paramètres!$G$12,1,4),2)+1+7*(A11-1) -> 46062 | C11: =B11+6 -> 46068 | D11: =COUNTIFS(Registre!$B$5:$B$1004,">="&$B11,Registre!$B$5:$B$1004,"<="&$C11) -> 0 | E11: =COUNTIFS(Registre!$R$5:$R$1004,">="&$B11,Registre!$R$5:$R$1004,"<="&$C11) -> 0 | F11: =COUNTIFS(Registre!$B$5:$B$1004,">="&$B11,Registre!$B$5:$B$1004,"<="&$C11,Registre!$L$5:$L$1004,"Très urgent")+COUNTIFS(Registre!$B$5:$B$1004,">="&$B11,Registre!$B$5:$B$1004,"<="&$C11,Registre!$L$5:$L$1004,"Urgent") -> 0 | G11: =IF($B11>TODAY(),"",COUNTIFS(Registre!$B$5:$B$1004,"<="&MIN($C11,TODAY()),Registre!$R$5:$R$1004,"",Registre!$Q$5:$Q$1004,"<>Classé sans suite")+COUNTIFS(Registre!$B$5:$B$1004,"<="&MIN($C11,TODAY()),Registre!$R$5:$R$1004,">"&MIN($C11,TODAY()))) -> 0 | H11: =IF($B11>TODAY(),"",COUNTIFS(Registre!$B$5:$B$1004,"<="&MIN($C11,TODAY()),Registre!$R$5:$R$1004,"",Registre!$P$5:$P$1004,"<"&MIN($C11,TODAY()),Registre!$Q$5:$Q$1004,"<>Classé sans suite")+COUNTIFS(Registre!$B$5:$B$1004,"<="&MIN($C11,TODAY()),Registre!$R$5:$R$1004,">"&MIN($C11,TODAY()),Registre!$P$5:$P$1004,"<"&MIN($C11,TODAY()))) -> 0 | I11: =IF(D11=0,"",COUNTIFS(Registre!$B$5:$B$1004,">="&$B11,Registre!$B$5:$B$1004,"<="&$C11,Registre!$R$5:$R$1004,"<>")/D11)
A12: 8 | B12: =DATE(Paramètres!$G$12,1,4)-WEEKDAY(DATE(Paramètres!$G$12,1,4),2)+1+7*(A12-1) -> 46069 | C12: =B12+6 -> 46075 | D12: =COUNTIFS(Registre!$B$5:$B$1004,">="&$B12,Registre!$B$5:$B$1004,"<="&$C12) -> 0 | E12: =COUNTIFS(Registre!$R$5:$R$1004,">="&$B12,Registre!$R$5:$R$1004,"<="&$C12) -> 0 | F12: =COUNTIFS(Registre!$B$5:$B$1004,">="&$B12,Registre!$B$5:$B$1004,"<="&$C12,Registre!$L$5:$L$1004,"Très urgent")+COUNTIFS(Registre!$B$5:$B$1004,">="&$B12,Registre!$B$5:$B$1004,"<="&$C12,Registre!$L$5:$L$1004,"Urgent") -> 0 | G12: =IF($B12>TODAY(),"",COUNTIFS(Registre!$B$5:$B$1004,"<="&MIN($C12,TODAY()),Registre!$R$5:$R$1004,"",Registre!$Q$5:$Q$1004,"<>Classé sans suite")+COUNTIFS(Registre!$B$5:$B$1004,"<="&MIN($C12,TODAY()),Registre!$R$5:$R$1004,">"&MIN($C12,TODAY()))) -> 0 | H12: =IF($B12>TODAY(),"",COUNTIFS(Registre!$B$5:$B$1004,"<="&MIN($C12,TODAY()),Registre!$R$5:$R$1004,"",Registre!$P$5:$P$1004,"<"&MIN($C12,TODAY()),Registre!$Q$5:$Q$1004,"<>Classé sans suite")+COUNTIFS(Registre!$B$5:$B$1004,"<="&MIN($C12,TODAY()),Registre!$R$5:$R$1004,">"&MIN($C12,TODAY()),Registre!$P$5:$P$1004,"<"&MIN($C12,TODAY()))) -> 0 | I12: =IF(D12=0,"",COUNTIFS(Registre!$B$5:$B$1004,">="&$B12,Registre!$B$5:$B$1004,"<="&$C12,Registre!$R$5:$R$1004,"<>")/D12)
A13: 9 | B13: =DATE(Paramètres!$G$12,1,4)-WEEKDAY(DATE(Paramètres!$G$12,1,4),2)+1+7*(A13-1) -> 46076 | C13: =B13+6 -> 46082 | D13: =COUNTIFS(Registre!$B$5:$B$1004,">="&$B13,Registre!$B$5:$B$1004,"<="&$C13) -> 0 | E13: =COUNTIFS(Registre!$R$5:$R$1004,">="&$B13,Registre!$R$5:$R$1004,"<="&$C13) -> 0 | F13: =COUNTIFS(Registre!$B$5:$B$1004,">="&$B13,Registre!$B$5:$B$1004,"<="&$C13,Registre!$L$5:$L$1004,"Très urgent")+COUNTIFS(Registre!$B$5:$B$1004,">="&$B13,Registre!$B$5:$B$1004,"<="&$C13,Registre!$L$5:$L$1004,"Urgent") -> 0 | G13: =IF($B13>TODAY(),"",COUNTIFS(Registre!$B$5:$B$1004,"<="&MIN($C13,TODAY()),Registre!$R$5:$R$1004,"",Registre!$Q$5:$Q$1004,"<>Classé sans suite")+COUNTIFS(Registre!$B$5:$B$1004,"<="&MIN($C13,TODAY()),Registre!$R$5:$R$1004,">"&MIN($C13,TODAY()))) -> 0 | H13: =IF($B13>TODAY(),"",COUNTIFS(Registre!$B$5:$B$1004,"<="&MIN($C13,TODAY()),Registre!$R$5:$R$1004,"",Registre!$P$5:$P$1004,"<"&MIN($C13,TODAY()),Registre!$Q$5:$Q$1004,"<>Classé sans suite")+COUNTIFS(Registre!$B$5:$B$1004,"<="&MIN($C13,TODAY()),Registre!$R$5:$R$1004,">"&MIN($C13,TODAY()),Registre!$P$5:$P$1004,"<"&MIN($C13,TODAY()))) -> 0 | I13: =IF(D13=0,"",COUNTIFS(Registre!$B$5:$B$1004,">="&$B13,Registre!$B$5:$B$1004,"<="&$C13,Registre!$R$5:$R$1004,"<>")/D13)
A14: 10 | B14: =DATE(Paramètres!$G$12,1,4)-WEEKDAY(DATE(Paramètres!$G$12,1,4),2)+1+7*(A14-1) -> 46083 | C14: =B14+6 -> 46089 | D14: =COUNTIFS(Registre!$B$5:$B$1004,">="&$B14,Registre!$B$5:$B$1004,"<="&$C14) -> 0 | E14: =COUNTIFS(Registre!$R$5:$R$1004,">="&$B14,Registre!$R$5:$R$1004,"<="&$C14) -> 0 | F14: =COUNTIFS(Registre!$B$5:$B$1004,">="&$B14,Registre!$B$5:$B$1004,"<="&$C14,Registre!$L$5:$L$1004,"Très urgent")+COUNTIFS(Registre!$B$5:$B$1004,">="&$B14,Registre!$B$5:$B$1004,"<="&$C14,Registre!$L$5:$L$1004,"Urgent") -> 0 | G14: =IF($B14>TODAY(),"",COUNTIFS(Registre!$B$5:$B$1004,"<="&MIN($C14,TODAY()),Registre!$R$5:$R$1004,"",Registre!$Q$5:$Q$1004,"<>Classé sans suite")+COUNTIFS(Registre!$B$5:$B$1004,"<="&MIN($C14,TODAY()),Registre!$R$5:$R$1004,">"&MIN($C14,TODAY()))) -> 0 | H14: =IF($B14>TODAY(),"",COUNTIFS(Registre!$B$5:$B$1004,"<="&MIN($C14,TODAY()),Registre!$R$5:$R$1004,"",Registre!$P$5:$P$1004,"<"&MIN($C14,TODAY()),Registre!$Q$5:$Q$1004,"<>Classé sans suite")+COUNTIFS(Registre!$B$5:$B$1004,"<="&MIN($C14,TODAY()),Registre!$R$5:$R$1004,">"&MIN($C14,TODAY()),Registre!$P$5:$P$1004,"<"&MIN($C14,TODAY()))) -> 0 | I14: =IF(D14=0,"",COUNTIFS(Registre!$B$5:$B$1004,">="&$B14,Registre!$B$5:$B$1004,"<="&$C14,Registre!$R$5:$R$1004,"<>")/D14)
A15: 11 | B15: =DATE(Paramètres!$G$12,1,4)-WEEKDAY(DATE(Paramètres!$G$12,1,4),2)+1+7*(A15-1) -> 46090 | C15: =B15+6 -> 46096 | D15: =COUNTIFS(Registre!$B$5:$B$1004,">="&$B15,Registre!$B$5:$B$1004,"<="&$C15) -> 0 | E15: =COUNTIFS(Registre!$R$5:$R$1004,">="&$B15,Registre!$R$5:$R$1004,"<="&$C15) -> 0 | F15: =COUNTIFS(Registre!$B$5:$B$1004,">="&$B15,Registre!$B$5:$B$1004,"<="&$C15,Registre!$L$5:$L$1004,"Très urgent")+COUNTIFS(Registre!$B$5:$B$1004,">="&$B15,Registre!$B$5:$B$1004,"<="&$C15,Registre!$L$5:$L$1004,"Urgent") -> 0 | G15: =IF($B15>TODAY(),"",COUNTIFS(Registre!$B$5:$B$1004,"<="&MIN($C15,TODAY()),Registre!$R$5:$R$1004,"",Registre!$Q$5:$Q$1004,"<>Classé sans suite")+COUNTIFS(Registre!$B$5:$B$1004,"<="&MIN($C15,TODAY()),Registre!$R$5:$R$1004,">"&MIN($C15,TODAY()))) -> 0 | H15: =IF($B15>TODAY(),"",COUNTIFS(Registre!$B$5:$B$1004,"<="&MIN($C15,TODAY()),Registre!$R$5:$R$1004,"",Registre!$P$5:$P$1004,"<"&MIN($C15,TODAY()),Registre!$Q$5:$Q$1004,"<>Classé sans suite")+COUNTIFS(Registre!$B$5:$B$1004,"<="&MIN($C15,TODAY()),Registre!$R$5:$R$1004,">"&MIN($C15,TODAY()),Registre!$P$5:$P$1004,"<"&MIN($C15,TODAY()))) -> 0 | I15: =IF(D15=0,"",COUNTIFS(Registre!$B$5:$B$1004,">="&$B15,Registre!$B$5:$B$1004,"<="&$C15,Registre!$R$5:$R$1004,"<>")/D15)
A16: 12 | B16: =DATE(Paramètres!$G$12,1,4)-WEEKDAY(DATE(Paramètres!$G$12,1,4),2)+1+7*(A16-1) -> 46097 | C16: =B16+6 -> 46103 | D16: =COUNTIFS(Registre!$B$5:$B$1004,">="&$B16,Registre!$B$5:$B$1004,"<="&$C16) -> 0 | E16: =COUNTIFS(Registre!$R$5:$R$1004,">="&$B16,Registre!$R$5:$R$1004,"<="&$C16) -> 0 | F16: =COUNTIFS(Registre!$B$5:$B$1004,">="&$B16,Registre!$B$5:$B$1004,"<="&$C16,Registre!$L$5:$L$1004,"Très urgent")+COUNTIFS(Registre!$B$5:$B$1004,">="&$B16,Registre!$B$5:$B$1004,"<="&$C16,Registre!$L$5:$L$1004,"Urgent") -> 0 | G16: =IF($B16>TODAY(),"",COUNTIFS(Registre!$B$5:$B$1004,"<="&MIN($C16,TODAY()),Registre!$R$5:$R$1004,"",Registre!$Q$5:$Q$1004,"<>Classé sans suite")+COUNTIFS(Registre!$B$5:$B$1004,"<="&MIN($C16,TODAY()),Registre!$R$5:$R$1004,">"&MIN($C16,TODAY()))) -> 0 | H16: =IF($B16>TODAY(),"",COUNTIFS(Registre!$B$5:$B$1004,"<="&MIN($C16,TODAY()),Registre!$R$5:$R$1004,"",Registre!$P$5:$P$1004,"<"&MIN($C16,TODAY()),Registre!$Q$5:$Q$1004,"<>Classé sans suite")+COUNTIFS(Registre!$B$5:$B$1004,"<="&MIN($C16,TODAY()),Registre!$R$5:$R$1004,">"&MIN($C16,TODAY()),Registre!$P$5:$P$1004,"<"&MIN($C16,TODAY()))) -> 0 | I16: =IF(D16=0,"",COUNTIFS(Registre!$B$5:$B$1004,">="&$B16,Registre!$B$5:$B$1004,"<="&$C16,Registre!$R$5:$R$1004,"<>")/D16)
... A57: 53 | B57: =DATE(Paramètres!$G$12,1,4)-WEEKDAY(DATE(Paramètres!$G$12,1,4),2)+1+7*(A57-1) -> 46384 | C57: =B57+6 -> 46390 | D57: =COUNTIFS(Registre!$B$5:$B$1004,">="&$B57,Registre!$B$5:$B$1004,"<="&$C57) -> 0 | E57: =COUNTIFS(Registre!$R$5:$R$1004,">="&$B57,Registre!$R$5:$R$1004,"<="&$C57) -> 0 | F57: =COUNTIFS(Registre!$B$5:$B$1004,">="&$B57,Registre!$B$5:$B$1004,"<="&$C57,Registre!$L$5:$L$1004,"Très urgent")+COUNTIFS(Registre!$B$5:$B$1004,">="&$B57,Registre!$B$5:$B$1004,"<="&$C57,Registre!$L$5:$L$1004,"Urgent") -> 0 | G57: =IF($B57>TODAY(),"",COUNTIFS(Registre!$B$5:$B$1004,"<="&MIN($C57,TODAY()),Registre!$R$5:$R$1004,"",Registre!$Q$5:$Q$1004,"<>Classé sans suite")+COUNTIFS(Registre!$B$5:$B$1004,"<="&MIN($C57,TODAY()),Registre!$R$5:$R$1004,">"&MIN($C57,TODAY()))) | H57: =IF($B57>TODAY(),"",COUNTIFS(Registre!$B$5:$B$1004,"<="&MIN($C57,TODAY()),Registre!$R$5:$R$1004,"",Registre!$P$5:$P$1004,"<"&MIN($C57,TODAY()),Registre!$Q$5:$Q$1004,"<>Classé sans suite")+COUNTIFS(Registre!$B$5:$B$1004,"<="&MIN($C57,TODAY()),Registre!$R$5:$R$1004,">"&MIN($C57,TODAY()),Registre!$P$5:$P$1004,"<"&MIN($C57,TODAY()))) | I57: =IF(D57=0,"",COUNTIFS(Registre!$B$5:$B$1004,">="&$B57,Registre!$B$5:$B$1004,"<="&$C57,Registre!$R$5:$R$1004,"<>")/D57)
A58: TOTAL | D58: =SUMPRODUCT((D5:D57)*(YEAR($B$5:$B$57+3)=Paramètres!$G$12)) -> 12 | E58: =SUMPRODUCT((E5:E57)*(YEAR($B$5:$B$57+3)=Paramètres!$G$12)) -> 6 | F58: =SUMPRODUCT((F5:F57)*(YEAR($B$5:$B$57+3)=Paramètres!$G$12)) -> 6 | I58: =IF(D58=0,"",COUNTIFS(Registre!$B$5:$B$1004,">="&B5,Registre!$B$5:$B$1004,"<="&MAX(C5:C57),Registre!$R$5:$R$1004,"<>")/D58) -> 0.5

Sheet Paramètres
A1: Paramètres et listes de référence
A2: Les cellules jaunes sont modifiables : adaptez les listes à l'organigramme du ministère (ajoutez des lignes en dessous si besoin).
A4: Services | B4: Types de courrier | C4: Catégories expéditeur | D4: Modes de réception | E4: Statuts | F4: Priorité | G4: Délai de traitement (jours)
A5: Cabinet du Ministre | B5: Lettre | C5: Administration publique | D5: Dépôt physique | E5: Reçu | F5: Très urgent | G5: 2
A6: Secrétariat Général | B6: Note de service | C6: Institution / Parlement | D6: Courrier postal | E6: Imputé | F6: Urgent | G6: 5
A7: Direction des Affaires Administratives et Financières | B7: Demande | C7: Partenaire technique et financier | D7: Courriel | E7: En cours | F7: Normal | G7: 15
A8: Direction des Ressources Humaines | B8: Réclamation | C8: Entreprise | D8: Valise / Coursier | E8: Traité | F8: Pour information | G8: 30
A9: Direction de la Planification et des Études | B9: Invitation | C9: Association / ONG | D9: Fax | E9: Classé sans suite
A10: Direction des Affaires Juridiques | B10: Rapport | C10: Particulier | F10: Délais indicatifs (en jours calendaires), à fixer selon les règles internes du ministère.
A11: Direction de la Communication | B11: Facture | C11: Autre
A12: Inspection Générale | B12: Convocation | F12: Année de la synthèse | G12: 2026
B13: Circulaire
B14: Autre
