Workbook

Sheet Lisez-moi
A1: Base de données du benchmark des prix agricoles – Côte d'Ivoire
A3: Objet | B3: Traçabilité complète des prix utilisés dans la note « Les prix agricoles ivoiriens sont-ils compétitifs ? » (octobre 2026).
A4: Date d'arrêté des données | B4: 1er octobre 2026 (dernières annonces : prix cacao/café 2026-27 du 01/09/2026 ; prix COCOBOD du 25/09/2026).
A5: Règle d'or | B5: Aucun graphique ni chiffre de la note n'est produit en dehors de cette base. Toutes les conversions sont des formules visibles.
A6: Codes couleur | B6: Bleu = donnée saisie (prix d'origine, taux) ; noir = formule ; vert = renvoi vers un autre onglet ; fond jaune = paramètre ou hypothèse à valider.
A7: Fiabilité | B7: A = source officielle primaire ; B = presse/agence reprenant une annonce officielle datée ; C = source secondaire, commerciale ou approximation (indicatif).
A8: Observations | B8: Une ligne par prix : produit, qualité, stade, campagne, pays, monnaie, unité, prix d'origine, taux de change de la même période, prix FCFA/kg, référence internationale, taux de transmission, source, URL, date de consultation, remarque.
A9: Change_mensuel / Change_periodes | B9: Taux mensuels (BCE pour l'euro et donc le FCFA ; BRI et banques centrales pour les autres monnaies) et moyennes exactes de chaque période de comparaison.
A10: Cours_mensuels / Cours_periodes | B10: Cours internationaux mensuels (Banque mondiale « Pink Sheet » jusqu'en janvier 2026, compléments FMI/OIC/SGX ensuite) et moyennes par période.
A11: Cacao_transmission | B11: Série 2016/17-2026/27 par demi-campagne : prix CI, prix Ghana, cours mondial, taux de transmission.
A12: Series_CI | B12: Prix officiels ivoiriens sur 10 campagnes, en nominal et en FCFA constants 2025 ; coefficients de variation.
A13: Indicateurs | B13: Comparaisons deux à deux (écart absolu, écart relatif, indice, transmission) et médianes des comparateurs.
A14: Decomposition | B14: Décomposition de la valeur (cacao, anacarde, caoutchouc, palmier).
... A19: Limites d'accès | B19: L'environnement de production n'autorisait pas le téléchargement direct (FAOSTAT, Comtrade, Eurostat, API Banque mondiale). Les fichiers primaires utilisés sont archivés dans SOURCES/donnees_primaires ; les autres chiffres proviennent des pages citées (URL).

Sheet Matrice
A1: Matrice de synthèse – compétitivité-prix des filières ivoiriennes
A3: Filière | B3: Prix CI (FCFA/kg) | C3: Benchmark (pays) | D3: Prix benchmark (FCFA/kg) | E3: Écart CI vs benchmark | F3: Part producteur / transmission | G3: Tendance (10 ans, nominal) | H3: Facteur explicatif principal | I3: Diagnostic | J3: Fiabilité
A4: Cacao | B4: =Indicateurs!E32 -> 1200 | C4: Ghana (ouverture 2026/27) | D4: =Indicateurs!F32 -> 2085.7803 | E4: =Indicateurs!H32 -> -0.42467575 | F4: =Indicateurs!J32 -> 0.35423886 | G4: =Series_CI!E17 -> 1.5454545 | H4: Ventes anticipées conclues au creux du marché (mars-juin 2026) ; règle ≥60 % CAF ; prélèvements ≈22 % du CAF ; Ghana : 70 % du FOB réalisé garanti par la loi | I4: Rémunération inférieure au benchmark ; transmission faible à court terme (décalage des ventes anticipées) | J4: A/B
A5: Café | B5: =Indicateurs!E33 -> 1300 | C5: Vietnam, Ouganda (2026) | D5: =Indicateurs!F33 -> 1916.6382 | E5: =Indicateurs!H33 -> -0.32172906 | F5: =Indicateurs!J33 -> 0.57695765 | G5: =Series_CI!G17 -> 1.2666667 | H5: Prix administré aligné sur ventes anticipées ; productivité très faible (production -70 % en 2024/25) | I5: Rémunération inférieure au benchmark ; problème de productivité plus que de prix | J5: A/B/C
A6: Anacarde | B6: =Indicateurs!E34 -> 400 | C6: Burkina, G.-Bissau, Ghana (2026) | D6: =Indicateurs!F34 -> 410 | E6: =Indicateurs!H34 -> -0.024390244 | F6: =Indicateurs!J34 -> 0.45694742 | G6: =Series_CI!H17 -> 0.21428571 | H6: Plancher aligné sur les voisins UEMOA ; forte valeur captée entre le port et le CFR Asie ; Ghana/Tanzanie mieux transmis (enchères, qualité) | I6: Prix au niveau des voisins UEMOA, nettement inférieur au Ghana ; valeur captée en aval du port | J6: B/C
A7: Coton | B7: =Indicateurs!E35 -> 310 | C7: Burkina, Mali, Bénin, Togo (2025/26) | D7: =Indicateurs!F35 -> 300 | E7: =Indicateurs!H35 -> 0.033333333 | F7: =Indicateurs!J35 -> 0.72795032 | G7: =Series_CI!I17 -> 0.16981132 | H7: Prix administré soutenu par une subvention de 25,3 Mds FCFA (2025/26) ; rendements dans la moyenne régionale | I7: Prix proche de la référence, soutenu par le budget | J7: A/B
A8: Caoutchouc | B8: =Indicateurs!E36 -> 806.66667 | C8: Thaïlande, Indonésie | D8: =Indicateurs!F36 -> 1144.0664 | E8: =Indicateurs!H36 -> -0.29491271 | F8: =Decomposition!B22 -> 0.59875527 | G8: n.d. | H8: Formule : 63-66 % d'un prix de référence net de coûts ; DRC conventionnel 60 % < DRC réel ; pouvoir de négociation des usiniers | I8: Transmission faible ; rémunération inférieure aux producteurs asiatiques | J8: B/C
A9: Palmier à huile | B9: =Indicateurs!E37 -> 80 | C9: Indonésie, Malaisie | D9: =Indicateurs!F37 -> 120.96905 | E9: =Indicateurs!H37 -> -0.33867382 | F9: =Decomposition!B28 -> 0.14347142 | G9: n.d. | H9: Prix du régime ≈14 % du prix mondial de l'huile brute contre ≈21-22 % en Asie (≈13 % du prix intérieur de l'huile), alors que l'huile brute est payée au-dessus du prix mondial sur le marché intérieur | I9: Rémunération inférieure ; partage de la valeur défavorable au planteur | J9: A/B
A10: Riz | B10: =Indicateurs!E38 -> 233 | C10: Sénégal (2025) | D10: =Indicateurs!F38 -> 130 | E10: =Indicateurs!H38 -> 0.79230769 | F10: =Observations!$Y$116 -> 1.5103939 | G10: n.d. | H10: Paddy payé au-dessus de la parité FOB du riz importé (équivalent paddy du riz thaï 5 %, hors fret et droits) : coûts de production et d'usinage élevés, rendements faibles | I10: Rémunération supérieure mais compétitivité faible face aux importations | J10: A/B
A11: Banane dessert | B11: n.d. | C11: Équateur (prix minimum) | D11: =Observations!$S$119 -> 216.93201 | E11: n.d. | F11: n.d. | G11: n.d. | H11: Filière intégrée (plantations exportatrices) : aucun prix producteur public en Côte d'Ivoire | I11: Données insuffisantes pour conclure | J11: B
A12: Mangue | B12: =Observations!$S$120 -> 220 | C12: Burkina Faso | D12: =Observations!$S$121 -> 95 | E12: n.c. | F12: n.d. | G12: n.d. | H12: Prix CI fixé en station (220 FCFA/kg) et à la caisse bord champ (poids non publié) : stades non comparables | I12: Données insuffisantes pour conclure | J12: B
A13: Ananas, maïs, manioc, igname, plantain, tomate, oignon, cola, coco, canne | B13: n.d. | C13: — | D13: n.d. | E13: n.d. | F13: n.d. | G13: n.d. | H13: Pas de prix bord champ public harmonisé (OCPV publie des prix à la consommation) ; FAOSTAT non accessible depuis l'environnement d'étude | I13: Données insuffisantes pour conclure | J13: —
A15: Lecture : écart = prix CI ÷ benchmark − 1 ; part producteur = prix CI ÷ référence internationale (caoutchouc : base sèche ; palmier : prix du régime ÷ prix mondial de l'huile ; riz : ÷ équivalent paddy du riz thaï 5 % FOB). n.d. = non disponible ; n.c. = non comparable.

Sheet Indicateurs
A1: Indicateurs de compétitivité-prix : comparaisons deux à deux (même produit, même stade, même période)
A3: Filière | B3: Comparaison | C3: ID Côte d'Ivoire | D3: ID comparateur | E3: Prix CI (FCFA/kg) | F3: Prix comparateur (FCFA/kg) | G3: I. Écart absolu (FCFA/kg) | H3: II. Écart relatif | I3: Indice CI (comparateur = 100) | J3: IV. Transmission CI | K3: IV. Transmission comparateur | L3: Comparabilité | M3: Commentaire
A4: Cacao | B4: Ghana – ouverture 2026/27 | C4: CAC-CI-2026/27-P | D4: CAC-GH-2026/27-P | E4: =Observations!$S$42 -> 1200 | F4: =Observations!$S$43 -> 2085.7803 | G4: =E4-F4 -> -885.78034 | H4: =E4/F4-1 -> -0.42467575 | I4: =E4/F4*100 -> 57.532425 | J4: =Observations!$Y$42 -> 0.35423886 | K4: =Observations!$Y$43 -> 0.61572037 | L4: Directe | M4: Deux prix administrés, même grade, même date ; Ghana = 71 % du FOB réalisé (Act 1182)
A5: Cacao | B5: Ghana – campagne principale 2025/26 | C5: CAC-CI-2025/26-P | D5: CAC-GH-2025/26-P | E5: =Observations!$S$20 -> 2800 | F5: =Observations!$S$40 -> 2964.4546 | G5: =E5-F5 -> -164.45457 | H5: =E5/F5-1 -> -0.055475489 | I5: =E5/F5*100 -> 94.452451 | J5: =Observations!$Y$20 -> 1.0252265 | K5: =Observations!$Y$40 -> 1.0854419 | L5: Directe | M5: Prix d'ouverture ; Ghana ramené à 41 392 GH¢/t au 12/02/2026
A6: Cacao | B6: Ghana – campagne intermédiaire 2025/26 | C6: CAC-CI-2025/26-I | D6: CAC-GH-2025/26-I | E6: =Observations!$S$21 -> 1200 | F6: =Observations!$S$41 -> 2059.1954 | G6: =E6-F6 -> -859.19544 | H6: =E6/F6-1 -> -0.41724813 | I6: =E6/F6*100 -> 58.275187 | J6: =Observations!$Y$21 -> 0.45005266 | K6: =Observations!$Y$41 -> 0.77228865 | L6: Directe
A7: Cacao | B7: Cameroun – mars-avril 2026 (marché libéralisé) | C7: CAC-CI-2025/26-I | D7: CAC-CM-2026-04 | E7: =Observations!$S$21 -> 1200 | F7: =Observations!$S$45 -> 1325 | G7: =E7-F7 -> -125 | H7: =E7/F7-1 -> -0.094339623 | I7: =E7/F7*100 -> 90.566038 | J7: =Observations!$Y$21 -> 0.45005266 | K7: =Observations!$Y$45 -> 0.70838523 | L7: Indicative | M7: Prix de marché relevé (fourchette) vs prix garanti
A8: Cacao | B8: Cameroun – fin juin 2026 | C8: CAC-CI-2025/26-I | D8: CAC-CM-2026-06 | E8: =Observations!$S$21 -> 1200 | F8: =Observations!$S$47 -> 2175 | G8: =E8-F8 -> -975 | H8: =E8/F8-1 -> -0.44827586 | I8: =E8/F8*100 -> 55.172414 | J8: =Observations!$Y$21 -> 0.45005266 | K8: =Observations!$Y$47 -> 0.86887366 | L8: Indicative | M8: Le marché libéralisé suit le cours mondial avec peu de retard
A9: Cacao | B9: Nigeria – sept. 2026 (source secondaire) | C9: CAC-CI-2026/27-P | D9: CAC-NG-2026-09 | E9: =Observations!$S$42 -> 1200 | F9: =Observations!$S$48 -> 2436.6927 | G9: =E9-F9 -> -1236.6927 | H9: =E9/F9-1 -> -0.5075292 | I9: =E9/F9*100 -> 49.24708 | J9: =Observations!$Y$42 -> 0.35423886 | K9: =Observations!$Y$48 -> 0.71930937 | L9: Indicative | M9: Source C : à confirmer
A10: Cacao | B10: Équateur – février 2026 | C10: CAC-CI-2025/26-P | D10: CAC-EC-2026-02 | E10: =Observations!$S$20 -> 2800 | F10: =Observations!$S$50 -> 1223.059 | G10: =E10-F10 -> 1576.941 | H10: =E10/F10-1 -> 1.2893418 | I10: =E10/F10*100 -> 228.93418 | J10: =Observations!$Y$20 -> 1.0252265 | K10: =Observations!$Y$50 -> 0.61458256 | L10: Indicative | M10: Qualités différentes (CCN-51/Nacional)
A11: Café | B11: Vietnam – fin sept. 2026 | C11: CAF-CI-2026/27 | D11: CAF-VN-2026-09 | E11: =Observations!$S$61 -> 1300 | F11: =Observations!$S$63 -> 2037.167 | G11: =E11-F11 -> -737.16704 | H11: =E11/F11-1 -> -0.36185891 | I11: =E11/F11*100 -> 63.814109 | J11: =Observations!$Y$61 -> 0.57695765 | K11: =Observations!$Y$63 -> 0.9041224 | L11: Directe | M11: Café vert robusta, prix bord champ/collecteur
A12: Café | B12: Ouganda – juillet 2026 | C12: CAF-CI-2025/26 | D12: CAF-UG-2026-07 | E12: =Observations!$S$60 -> 1700 | F12: =Observations!$S$62 -> 1796.1094 | G12: =E12-F12 -> -96.109383 | H12: =E12/F12-1 -> -0.053509761 | I12: =E12/F12*100 -> 94.649024 | J12: =Observations!$Y$60 -> 0.7385801 | K12: =Observations!$Y$62 -> 0.76556593 | L12: Directe | M12: FAQ ≈ café vert non classé ; taux de change de source C
A13: Anacarde | B13: Burkina Faso – 2026 | C13: ANA-CI-2026 | D13: ANA-BF-2026 | E13: =Observations!$S$74 -> 400 | F13: =Observations!$S$77 -> 385 | G13: =E13-F13 -> 15 | H13: =E13/F13-1 -> 0.038961039 | I13: =E13/F13*100 -> 103.8961 | J13: =Observations!$Y$74 -> 0.45694742 | K13: =Observations!$Y$77 -> 0.43981189 | L13: Directe | M13: Deux prix planchers, même devise
A14: Anacarde | B14: Guinée-Bissau – 2026 | C14: ANA-CI-2026 | D14: ANA-GW-2026 | E14: =Observations!$S$74 -> 400 | F14: =Observations!$S$78 -> 410 | G14: =E14-F14 -> -10 | H14: =E14/F14-1 -> -0.024390244 | I14: =E14/F14*100 -> 97.560976 | J14: =Observations!$Y$74 -> 0.45694742 | K14: =Observations!$Y$78 -> 0.4683711 | L14: Directe | M14: Prix de référence producteur
A15: Anacarde | B15: Ghana – 2026 | C15: ANA-CI-2026 | D15: ANA-GH-2026 | E15: =Observations!$S$74 -> 400 | F15: =Observations!$S$80 -> 607.91081 | G15: =E15-F15 -> -207.91081 | H15: =E15/F15-1 -> -0.34200874 | I15: =E15/F15*100 -> 65.799126 | J15: =Observations!$Y$74 -> 0.45694742 | K15: =Observations!$Y$80 -> 0.69445819 | L15: Directe | M15: Prix minimum ; respect effectif non documenté
A16: Anacarde | B16: Tanzanie – 2025/26 (enchères) | C16: ANA-CI-2026 | D16: ANA-TZ-2025/26 | E16: =Observations!$S$74 -> 400 | F16: =Observations!$S$82 -> 691.81801 | G16: =E16-F16 -> -291.81801 | H16: =E16/F16-1 -> -0.42181326 | I16: =E16/F16*100 -> 57.818674 | J16: =Observations!$Y$74 -> 0.45694742 | K16: =Observations!$Y$82 -> 0.79031113 | L16: Indicative | M16: Saison et qualité (KOR) différentes ; prix d'enchère en magasin primaire
A17: Anacarde | B17: Mali – 2025 | C17: ANA-CI-2025 | D17: ANA-ML-2025 | E17: =Observations!$S$73 -> 425 | F17: =Observations!$S$79 -> 390 | G17: =E17-F17 -> 35 | H17: =E17/F17-1 -> 0.08974359 | I17: =E17/F17*100 -> 108.97436 | J17: =Observations!$Y$73 | K17: =Observations!$Y$79 | L17: Directe | M17: Même année (2025)
A18: Coton | B18: Burkina Faso – 2025/26 | C18: COT-CI-2025/26 | D18: COT-BF-2025/26 | E18: =Observations!$S$93 -> 310 | F18: =Observations!$S$94 -> 325 | G18: =E18-F18 -> -15 | H18: =E18/F18-1 -> -0.046153846 | I18: =E18/F18*100 -> 95.384615 | J18: =Observations!$Y$93 -> 0.72795032 | K18: =Observations!$Y$94 | L18: Directe | M18: Prix administrés, même qualité (1er choix)
A19: Coton | B19: Mali – 2025/26 | C19: COT-CI-2025/26 | D19: COT-ML-2025/26 | E19: =Observations!$S$93 -> 310 | F19: =Observations!$S$95 -> 300 | G19: =E19-F19 -> 10 | H19: =E19/F19-1 -> 0.033333333 | I19: =E19/F19*100 -> 103.33333 | J19: =Observations!$Y$93 -> 0.72795032 | K19: =Observations!$Y$95 | L19: Directe
A20: Coton | B20: Bénin – 2025/26 | C20: COT-CI-2025/26 | D20: COT-BJ-2025/26 | E20: =Observations!$S$93 -> 310 | F20: =Observations!$S$96 -> 300 | G20: =E20-F20 -> 10 | H20: =E20/F20-1 -> 0.033333333 | I20: =E20/F20*100 -> 103.33333 | J20: =Observations!$Y$93 -> 0.72795032 | K20: =Observations!$Y$96 | L20: Directe | M20: Coton conventionnel
A21: Coton | B21: Togo – 2025/26 | C21: COT-CI-2025/26 | D21: COT-TG-2025/26 | E21: =Observations!$S$93 -> 310 | F21: =Observations!$S$97 -> 300 | G21: =E21-F21 -> 10 | H21: =E21/F21-1 -> 0.033333333 | I21: =E21/F21*100 -> 103.33333 | J21: =Observations!$Y$93 -> 0.72795032 | K21: =Observations!$Y$97 | L21: Directe | M21: Source C
A22: Coton | B22: Sénégal – 2025/26 | C22: COT-CI-2025/26 | D22: COT-SN-2025/26 | E22: =Observations!$S$93 -> 310 | F22: =Observations!$S$98 -> 350 | G22: =E22-F22 -> -40 | H22: =E22/F22-1 -> -0.11428571 | I22: =E22/F22*100 -> 88.571429 | J22: =Observations!$Y$93 -> 0.72795032 | K22: =Observations!$Y$98 | L22: Indicative | M22: « Jusqu'à 350 FCFA » : source C
A23: Caoutchouc | B23: Thaïlande – mai 2025 (base sèche) | C23: CAO-CI-2025-04 | D23: CAO-TH-2025-05 | E23: =Observations!$V$102 -> 730 | F23: =Observations!$V$109 -> 1004.295 | G23: =E23-F23 -> -274.29498 | H23: =E23/F23-1 -> -0.27312193 | I23: =E23/F23*100 -> 72.687807 | J23: =Observations!$Y$102 -> 0.60691659 | K23: =Observations!$Y$109 -> 1.0060933 | L23: Indicative | M23: CI converti en kg sec (DRC 60 %) ; un mois d'écart
A24: Caoutchouc | B24: Indonésie – août/sept. 2026 (base sèche) | C24: CAO-CI-2026-09 | D24: CAO-ID-2026-08 | E24: =Observations!$V$108 -> 806.66667 | F24: =Observations!$V$110 -> 1283.8378 | G24: =E24-F24 -> -477.17111 | H24: =E24/F24-1 -> -0.37167555 | I24: =E24/F24*100 -> 62.832445 | J24: =Observations!$Y$108 | K24: =Observations!$Y$110 | L24: Indicative | M24: Prix de référence provincial ; un mois d'écart
A25: Palmier à huile | B25: Indonésie (Riau) – janvier 2026 | C25: PAL-CI-FFB-2026-01 | D25: PAL-ID-FFB-2026-01 | E25: =Observations!$S$111 -> 80 | F25: =Observations!$S$114 -> 114.8472 | G25: =E25-F25 -> -34.847202 | H25: =E25/F25-1 -> -0.3034223 | I25: =E25/F25*100 -> 69.65777 | J25: =Observations!$Y$111 -> 0.14347142 | K25: =Observations!$Y$114 -> 0.20596614 | L25: Indicative | M25: Bord champ (CI) vs livraison usine (Riau)
A26: Palmier à huile | B26: Malaisie – 2025 vs CI janv. 2026 | C26: PAL-CI-FFB-2026-01 | D26: PAL-MY-FFB-2025 | E26: =Observations!$S$111 -> 80 | F26: =Observations!$S$115 -> 127.0909 | G26: =E26-F26 -> -47.090897 | H26: =E26/F26-1 -> -0.37052927 | I26: =E26/F26*100 -> 62.947073 | J26: =Observations!$Y$111 -> 0.14347142 | K26: =Observations!$Y$115 -> 0.21688915 | L26: Indicative | M26: Périodes proches mais différentes
A27: Riz | B27: Sénégal – 2025 | C27: RIZ-CI-2025 | D27: RIZ-SN-2025 | E27: =Observations!$S$116 -> 233 | F27: =Observations!$S$117 -> 130 | G27: =E27-F27 -> 103 | H27: =E27/F27-1 -> 0.79230769 | I27: =E27/F27*100 -> 179.23077 | J27: =Observations!$Y$116 -> 1.5103939 | K27: =Observations!$Y$117 -> 0.84270905 | L27: Directe | M27: Prix producteur fixé (130) ; usiniers 160 avec subvention
A28: Riz | B28: Vietnam – fin 2025 (paddy frais) | C28: RIZ-CI-2025 | D28: RIZ-VN-2025 | E28: =Observations!$S$116 -> 233 | F28: =Observations!$S$118 -> 123.69116 | G28: =E28-F28 -> 109.30884 | H28: =E28/F28-1 -> 0.88372396 | I28: =E28/F28*100 -> 188.3724 | J28: =Observations!$Y$116 -> 1.5103939 | K28: =Observations!$Y$118 -> 0.80181277 | L28: Indicative | M28: Paddy frais (humide) vs paddy sec
A30: III. Position relative : médiane des comparateurs directs de la même période (à défaut de comparateur direct : médiane des comparateurs indicatifs, résultat indicatif)
A31: Filière | B31: Période de référence | C31: ID CI | D31: Statut du benchmark | E31: Prix CI (FCFA/kg) | F31: Médiane comparateurs (FCFA/kg) | G31: Écart absolu | H31: Écart relatif | I31: Indice CI (médiane = 100) | J31: Transmission CI | K31: Médiane transmission comparateurs | L31: Nb comparateurs | M31: Comparateurs retenus
A32: Cacao | B32: Ouverture 2026/27 | C32: CAC-CI-2026/27-P | D32: Directs | E32: =Observations!$S$42 -> 1200 | F32: =MEDIAN(Observations!$S$43) -> 2085.7803 | G32: =E32-F32 -> -885.78034 | H32: =E32/F32-1 -> -0.42467575 | I32: =E32/F32*100 -> 57.532425 | J32: =Observations!$Y$42 -> 0.35423886 | K32: =IFERROR(MEDIAN(Observations!$Y$43),"") -> 0.61572037 | L32: 1 | M32: Ghana (seul comparateur direct à la même date ; Nigeria sept. 2026 exclu : source C, comparaison indicative)
A33: Café | B33: Sept. 2026 (CI 2026/27) | C33: CAF-CI-2026/27 | D33: Directs | E33: =Observations!$S$61 -> 1300 | F33: =MEDIAN(Observations!$S$63,Observations!$S$62) -> 1916.6382 | G33: =E33-F33 -> -616.63821 | H33: =E33/F33-1 -> -0.32172906 | I33: =E33/F33*100 -> 67.827094 | J33: =Observations!$Y$61 -> 0.57695765 | K33: =IFERROR(MEDIAN(Observations!$Y$63,Observations!$Y$62),"") -> 0.83484417 | L33: 2 | M33: Vietnam (sept. 2026), Ouganda (juil. 2026)
A34: Anacarde | B34: Campagne 2026 | C34: ANA-CI-2026 | D34: Directs | E34: =Observations!$S$74 -> 400 | F34: =MEDIAN(Observations!$S$77,Observations!$S$78,Observations!$S$80) -> 410 | G34: =E34-F34 -> -10 | H34: =E34/F34-1 -> -0.024390244 | I34: =E34/F34*100 -> 97.560976 | J34: =Observations!$Y$74 -> 0.45694742 | K34: =IFERROR(MEDIAN(Observations!$Y$77,Observations!$Y$78,Observations!$Y$80),"") -> 0.4683711 | L34: 3 | M34: Burkina, Guinée-Bissau, Ghana (Tanzanie exclue : saison, qualité et stade différents, comparaison indicative)
A35: Coton | B35: Campagne 2025/26 | C35: COT-CI-2025/26 | D35: Directs | E35: =Observations!$S$93 -> 310 | F35: =MEDIAN(Observations!$S$94,Observations!$S$95,Observations!$S$96,Observations!$S$97) -> 300 | G35: =E35-F35 -> 10 | H35: =E35/F35-1 -> 0.033333333 | I35: =E35/F35*100 -> 103.33333 | J35: =Observations!$Y$93 -> 0.72795032 | K35: =IFERROR(MEDIAN(Observations!$Y$94,Observations!$Y$95,Observations!$Y$96,Observations!$Y$97),"") | L35: 4 | M35: Burkina, Mali, Bénin, Togo (Sénégal exclu : comparaison indicative)
A36: Caoutchouc | B36: 2025-2026 (base sèche) | C36: CAO-CI-2026-09 | D36: Indicatifs (aucun direct) | E36: =Observations!$V$108 -> 806.66667 | F36: =MEDIAN(Observations!$V$109,Observations!$V$110) -> 1144.0664 | G36: =E36-F36 -> -337.39971 | H36: =E36/F36-1 -> -0.29491271 | I36: =E36/F36*100 -> 70.508729 | J36: =Observations!$Y$108 | K36: =IFERROR(MEDIAN(Observations!$Y$109,Observations!$Y$110),"") -> 1.0060933 | L36: 2 | M36: Thaïlande (mai 2025), Indonésie (août 2026)
A37: Palmier à huile | B37: Janv. 2026 / 2025 | C37: PAL-CI-FFB-2026-01 | D37: Indicatifs (aucun direct) | E37: =Observations!$S$111 -> 80 | F37: =MEDIAN(Observations!$S$114,Observations!$S$115) -> 120.96905 | G37: =E37-F37 -> -40.96905 | H37: =E37/F37-1 -> -0.33867382 | I37: =E37/F37*100 -> 66.132618 | J37: =Observations!$Y$111 -> 0.14347142 | K37: =IFERROR(MEDIAN(Observations!$Y$114,Observations!$Y$115),"") -> 0.21142764 | L37: 2 | M37: Indonésie (Riau), Malaisie
A38: Riz | B38: 2025 | C38: RIZ-CI-2025 | D38: Directs | E38: =Observations!$S$116 -> 233 | F38: =MEDIAN(Observations!$S$117) -> 130 | G38: =E38-F38 -> 103 | H38: =E38/F38-1 -> 0.79230769 | I38: =E38/F38*100 -> 179.23077 | J38: =Observations!$Y$116 -> 1.5103939 | K38: =IFERROR(MEDIAN(Observations!$Y$117),"") -> 0.84270905 | L38: 1 | M38: Sénégal (Vietnam exclu : paddy frais, comparaison indicative)
A40: VI. Transmission moyenne sur la durée (prix CI ÷ cours international de la même campagne)
A41: Filière | B41: Période | E41: Moyenne CI | F41: Moyenne 3 dernières campagnes | M41: Note
A42: Café | B42: 2016/17-2025/26 | E42: =AVERAGE(Observations!$Y$51,Observations!$Y$52,Observations!$Y$53,Observations!$Y$54,Observations!$Y$55,Observations!$Y$56,Observations!$Y$57,Observations!$Y$58,Observations!$Y$59,Observations!$Y$60) -> 0.59434815 | F42: =AVERAGE(Observations!$Y$58,Observations!$Y$59,Observations!$Y$60) -> 0.54392516 | M42: Robusta (indicateur OIC) ; 2025/26 : oct. 2025-août 2026
A43: Coton | B43: 2017/18-2025/26 | E43: =AVERAGE(Observations!$Y$85,Observations!$Y$86,Observations!$Y$87,Observations!$Y$88,Observations!$Y$89,Observations!$Y$90,Observations!$Y$91,Observations!$Y$92,Observations!$Y$93) -> 0.58600087 | F43: =AVERAGE(Observations!$Y$91,Observations!$Y$92,Observations!$Y$93) -> 0.64572195 | M43: Équivalent fibre (rendement à l'égrenage) ÷ indice A ; 2025/26 partiel
...

Sheet Observations
A1: ID | B1: Filière | C1: Produit exact | D1: Pays | E1: Année / campagne | F1: Période couverte | G1: Type de prix | H1: Stade de commercialisation | I1: Qualité / spécification | J1: Prix original | K1: Monnaie | L1: Unité d'origine | M1: kg par unité | N1: Code période (change) | O1: Taux de change (monnaie / USD) | P1: Source du taux de change | Q1: Taux FCFA / USD (même période) | R1: Prix USD/kg | S1: Prix FCFA/kg | T1: Facteur d'équivalence | U1: Base de comparaison | V1: Prix FCFA/kg (base de comparaison) | W1: ID référence internationale | X1: Prix international de référence (FCFA/kg) | Y1: Taux de transmission | Z1: ID valeur FOB/CAF nationale | AA1: Valeur FOB/CAF (FCFA/kg) | AB1: Part producteur dans FOB/CAF | AC1: Source | AD1: URL | AE1: Date de consultation | AF1: Fiabilité | AG1: Remarque méthodologique
A2: CAC-CI-2016/17-P | B2: Cacao | C2: Fèves de cacao marchandes | D2: Côte d'Ivoire | E2: 2016/17 | F2: Campagne principale (oct.-mars) | G2: Prix minimum garanti (administré) | H2: Bord champ | I2: Bien fermenté, séché, trié (grade marchand) | J2: 1100 | K2: XOF | L2: kg | M2: 1 | N2: 2016-10:2017-03 | O2: =IF(K2="USD",1,INDEX(Change_periodes!$D$1:$N$400,MATCH($N2,Change_periodes!$A$1:$A$400,0),MATCH($K2,Change_periodes!$D$1:$N$1,0))) -> 612.12961 | P2: BCE (parité fixe 655,957 FCFA/EUR) | Q2: =INDEX(Change_periodes!$D$1:$D$400,MATCH($N2,Change_periodes!$A$1:$A$400,0)) -> 612.12961 | R2: =IFERROR(J2/M2/O2,"") -> 1.797005 | S2: =IFERROR(R2*Q2,"") -> 1100 | T2: 1 | U2: FCFA/kg de produit tel que vendu | V2: =IFERROR(S2/T2,"") -> 1100 | W2: INT-CAC-2016/17-P | X2: =IF(W2="","",IFERROR(INDEX($V$1:$V$178,MATCH(W2,$A$1:$A$178,0)),"")) -> 1405.57 | Y2: =IF(OR(X2="",V2=""),"",V2/X2) -> 0.78260066 | AA2: =IF(Z2="","",IFERROR(INDEX($V$1:$V$178,MATCH(Z2,$A$1:$A$178,0)),"")) | AB2: =IF(OR(AA2="",V2=""),"",V2/AA2) | AC2: CCC / Gouvernement (via Connectionivoirienne) – Le kilo de cacao à 1 100 FCFA pour la campagne 2016-2017 | AD2: https://connectionivoirienne.net/2016/09/28/cote-divoire-le-kilo-de-cacao-a-1-100-fcfa-pour-la-campagne-2016-2017 | AE2: 2026-10-01 | AF2: B | AG2: Prix administré par le CCC ; ventes anticipées ; règle ≥60 % du prix CAF de référence
A3: CAC-CI-2016/17-I | B3: Cacao | C3: Fèves de cacao marchandes | D3: Côte d'Ivoire | E3: 2016/17 | F3: Campagne intermédiaire (avr.-sept.) | G3: Prix minimum garanti (administré) | H3: Bord champ | I3: Bien fermenté, séché, trié (grade marchand) | J3: 700 | K3: XOF | L3: kg | M3: 1 | N3: 2017-04:2017-09 | O3: =IF(K3="USD",1,INDEX(Change_periodes!$D$1:$N$400,MATCH($N3,Change_periodes!$A$1:$A$400,0),MATCH($K3,Change_periodes!$D$1:$N$1,0))) -> 577.51424 | P3: BCE (parité fixe 655,957 FCFA/EUR) | Q3: =INDEX(Change_periodes!$D$1:$D$400,MATCH($N3,Change_periodes!$A$1:$A$400,0)) -> 577.51424 | R3: =IFERROR(J3/M3/O3,"") -> 1.2120913 | S3: =IFERROR(R3*Q3,"") -> 700 | T3: 1 | U3: FCFA/kg de produit tel que vendu | V3: =IFERROR(S3/T3,"") -> 700 | W3: INT-CAC-2016/17-I | X3: =IF(W3="","",IFERROR(INDEX($V$1:$V$178,MATCH(W3,$A$1:$A$178,0)),"")) -> 1147.1675 | Y3: =IF(OR(X3="",V3=""),"",V3/X3) -> 0.61019857 | AA3: =IF(Z3="","",IFERROR(INDEX($V$1:$V$178,MATCH(Z3,$A$1:$A$178,0)),"")) | AB3: =IF(OR(AA3="",V3=""),"",V3/AA3) | AC3: CCC (via Connectionivoirienne) – Prix bord champ du cacao pour la campagne intermédiaire fixé à 700 FCFA | AD3: https://connectionivoirienne.net/2017/03/30/cote-divoire-le-prix-bord-champ-du-cacao-pour-la-campagne-intermediaire-fixe-a-700-fcfa-1-euro/ | AE3: 2026-10-01 | AF3: B | AG3: Prix administré par le CCC ; ventes anticipées ; règle ≥60 % du prix CAF de référence
A4: CAC-CI-2017/18-P | B4: Cacao | C4: Fèves de cacao marchandes | D4: Côte d'Ivoire | E4: 2017/18 | F4: Campagne principale (oct.-mars) | G4: Prix minimum garanti (administré) | H4: Bord champ | I4: Bien fermenté, séché, trié (grade marchand) | J4: 700 | K4: XOF | L4: kg | M4: 1 | N4: 2017-10:2018-03 | O4: =IF(K4="USD",1,INDEX(Change_periodes!$D$1:$N$400,MATCH($N4,Change_periodes!$A$1:$A$400,0),MATCH($K4,Change_periodes!$D$1:$N$1,0))) -> 545.27827 | P4: BCE (parité fixe 655,957 FCFA/EUR) | Q4: =INDEX(Change_periodes!$D$1:$D$400,MATCH($N4,Change_periodes!$A$1:$A$400,0)) -> 545.27827 | R4: =IFERROR(J4/M4/O4,"") -> 1.2837482 | S4: =IFERROR(R4*Q4,"") -> 700 | T4: 1 | U4: FCFA/kg de produit tel que vendu | V4: =IFERROR(S4/T4,"") -> 700 | W4: INT-CAC-2017/18-P | X4: =IF(W4="","",IFERROR(INDEX($V$1:$V$178,MATCH(W4,$A$1:$A$178,0)),"")) -> 1156.0999 | Y4: =IF(OR(X4="",V4=""),"",V4/X4) -> 0.60548401 | AA4: =IF(Z4="","",IFERROR(INDEX($V$1:$V$178,MATCH(Z4,$A$1:$A$178,0)),"")) | AB4: =IF(OR(AA4="",V4=""),"",V4/AA4) | AC4: CCC (via Connectionivoirienne) – Le prix d'achat au producteur de cacao maintenu à 700 FCFA (campagne intermédiaire 2017-2018) | AD4: https://connectionivoirienne.net/2018/03/30/le-prix-dachat-au-producteur-de-cacao-en-cote-divoire-maintenu-a-700-francs-cfa | AE4: 2026-10-01 | AF4: B | AG4: Prix administré par le CCC ; ventes anticipées ; règle ≥60 % du prix CAF de référence
A5: CAC-CI-2017/18-I | B5: Cacao | C5: Fèves de cacao marchandes | D5: Côte d'Ivoire | E5: 2017/18 | F5: Campagne intermédiaire (avr.-sept.) | G5: Prix minimum garanti (administré) | H5: Bord champ | I5: Bien fermenté, séché, trié (grade marchand) | J5: 700 | K5: XOF | L5: kg | M5: 1 | N5: 2018-04:2018-09 | O5: =IF(K5="USD",1,INDEX(Change_periodes!$D$1:$N$400,MATCH($N5,Change_periodes!$A$1:$A$400,0),MATCH($K5,Change_periodes!$D$1:$N$1,0))) -> 557.21356 | P5: BCE (parité fixe 655,957 FCFA/EUR) | Q5: =INDEX(Change_periodes!$D$1:$D$400,MATCH($N5,Change_periodes!$A$1:$A$400,0)) -> 557.21356 | R5: =IFERROR(J5/M5/O5,"") -> 1.2562508 | S5: =IFERROR(R5*Q5,"") -> 700 | T5: 1 | U5: FCFA/kg de produit tel que vendu | V5: =IFERROR(S5/T5,"") -> 700 | W5: INT-CAC-2017/18-I | X5: =IF(W5="","",IFERROR(INDEX($V$1:$V$178,MATCH(W5,$A$1:$A$178,0)),"")) -> 1339.0761 | Y5: =IF(OR(X5="",V5=""),"",V5/X5) -> 0.52274847 | AA5: =IF(Z5="","",IFERROR(INDEX($V$1:$V$178,MATCH(Z5,$A$1:$A$178,0)),"")) | AB5: =IF(OR(AA5="",V5=""),"",V5/AA5) | AC5: CCC (via Connectionivoirienne) – Le prix d'achat au producteur de cacao maintenu à 700 FCFA (campagne intermédiaire 2017-2018) | AD5: https://connectionivoirienne.net/2018/03/30/le-prix-dachat-au-producteur-de-cacao-en-cote-divoire-maintenu-a-700-francs-cfa | AE5: 2026-10-01 | AF5: B | AG5: Prix administré par le CCC ; ventes anticipées ; règle ≥60 % du prix CAF de référence
A6: CAC-CI-2018/19-P | B6: Cacao | C6: Fèves de cacao marchandes | D6: Côte d'Ivoire | E6: 2018/19 | F6: Campagne principale (oct.-mars) | G6: Prix minimum garanti (administré) | H6: Bord champ | I6: Bien fermenté, séché, trié (grade marchand) | J6: 750 | K6: XOF | L6: kg | M6: 1 | N6: 2018-10:2019-03 | O6: =IF(K6="USD",1,INDEX(Change_periodes!$D$1:$N$400,MATCH($N6,Change_periodes!$A$1:$A$400,0),MATCH($K6,Change_periodes!$D$1:$N$1,0))) -> 576.214 | P6: BCE (parité fixe 655,957 FCFA/EUR) | Q6: =INDEX(Change_periodes!$D$1:$D$400,MATCH($N6,Change_periodes!$A$1:$A$400,0)) -> 576.214 | R6: =IFERROR(J6/M6/O6,"") -> 1.3015998 | S6: =IFERROR(R6*Q6,"") -> 750 | T6: 1 | U6: FCFA/kg de produit tel que vendu | V6: =IFERROR(S6/T6,"") -> 750 | W6: INT-CAC-2018/19-P | X6: =IF(W6="","",IFERROR(INDEX($V$1:$V$178,MATCH(W6,$A$1:$A$178,0)),"")) -> 1272.2114 | Y6: =IF(OR(X6="",V6=""),"",V6/X6) -> 0.58952468 | AA6: =IF(Z6="","",IFERROR(INDEX($V$1:$V$178,MATCH(Z6,$A$1:$A$178,0)),"")) | AB6: =IF(OR(AA6="",V6=""),"",V6/AA6) | AC6: CCC (via Agence Ecofin) – Cocoa farm-gate price set to CFA750 per kilo for 2018/2019 season | AD6: https://www.ecofinagency.com/agriculture/0210-39023-cote-d-ivoire-cocoa-farm-gate-price-set-to-cfa750-per-kilo-for-2018/2019-season | AE6: 2026-10-01 | AF6: B | AG6: Prix administré par le CCC ; ventes anticipées ; règle ≥60 % du prix CAF de référence
A7: CAC-CI-2018/19-I | B7: Cacao | C7: Fèves de cacao marchandes | D7: Côte d'Ivoire | E7: 2018/19 | F7: Campagne intermédiaire (avr.-sept.) | G7: Prix minimum garanti (administré) | H7: Bord champ | I7: Bien fermenté, séché, trié (grade marchand) | J7: 750 | K7: XOF | L7: kg | M7: 1 | N7: 2019-04:2019-09 | O7: =IF(K7="USD",1,INDEX(Change_periodes!$D$1:$N$400,MATCH($N7,Change_periodes!$A$1:$A$400,0),MATCH($K7,Change_periodes!$D$1:$N$1,0))) -> 586.8976 | P7: BCE (parité fixe 655,957 FCFA/EUR) | Q7: =INDEX(Change_periodes!$D$1:$D$400,MATCH($N7,Change_periodes!$A$1:$A$400,0)) -> 586.8976 | R7: =IFERROR(J7/M7/O7,"") -> 1.2779061 | S7: =IFERROR(R7*Q7,"") -> 750 | T7: 1 | U7: FCFA/kg de produit tel que vendu | V7: =IFERROR(S7/T7,"") -> 750 | W7: INT-CAC-2018/19-I | X7: =IF(W7="","",IFERROR(INDEX($V$1:$V$178,MATCH(W7,$A$1:$A$178,0)),"")) -> 1366.551 | Y7: =IF(OR(X7="",V7=""),"",V7/X7) -> 0.54882695 | AA7: =IF(Z7="","",IFERROR(INDEX($V$1:$V$178,MATCH(Z7,$A$1:$A$178,0)),"")) | AB7: =IF(OR(AA7="",V7=""),"",V7/AA7) | AC7: Gouvernement (via Afrique-sur7) – Le gouvernement maintient le prix du cacao à 750 FCFA pour la campagne intermédiaire | AD7: https://www.afrique-sur7.fr/420663-prix-cacao-750-campagne-intermediaire | AE7: 2026-10-01 | AF7: B | AG7: Prix administré par le CCC ; ventes anticipées ; règle ≥60 % du prix CAF de référence
A8: CAC-CI-2019/20-P | B8: Cacao | C8: Fèves de cacao marchandes | D8: Côte d'Ivoire | E8: 2019/20 | F8: Campagne principale (oct.-mars) | G8: Prix minimum garanti (administré) | H8: Bord champ | I8: Bien fermenté, séché, trié (grade marchand) | J8: 825 | K8: XOF | L8: kg | M8: 1 | N8: 2019-10:2020-03 | O8: =IF(K8="USD",1,INDEX(Change_periodes!$D$1:$N$400,MATCH($N8,Change_periodes!$A$1:$A$400,0),MATCH($K8,Change_periodes!$D$1:$N$1,0))) -> 593.77663 | P8: BCE (parité fixe 655,957 FCFA/EUR) | Q8: =INDEX(Change_periodes!$D$1:$D$400,MATCH($N8,Change_periodes!$A$1:$A$400,0)) -> 593.77663 | R8: =IFERROR(J8/M8/O8,"") -> 1.3894114 | S8: =IFERROR(R8*Q8,"") -> 825 | T8: 1 | U8: FCFA/kg de produit tel que vendu | V8: =IFERROR(S8/T8,"") -> 825 | W8: INT-CAC-2019/20-P | X8: =IF(W8="","",IFERROR(INDEX($V$1:$V$178,MATCH(W8,$A$1:$A$178,0)),"")) -> 1490.121 | Y8: =IF(OR(X8="",V8=""),"",V8/X8) -> 0.5536463 | AA8: =IF(Z8="","",IFERROR(INDEX($V$1:$V$178,MATCH(Z8,$A$1:$A$178,0)),"")) | AB8: =IF(OR(AA8="",V8=""),"",V8/AA8) | AC8: CCC (via Connectionivoirienne) – Le prix du kg de cacao fixé à 825 FCFA pour la campagne 2019-2020 | AD8: https://connectionivoirienne.net/2019/10/01/le-prix-du-kg-de-cacao-fixe-a-825-fcfa-en-cote-divoire-pour-la-campagne-2019-2020/ | AE8: 2026-10-01 | AF8: B | AG8: Prix administré par le CCC ; ventes anticipées ; règle ≥60 % du prix CAF de référence
A9: CAC-CI-2019/20-I | B9: Cacao | C9: Fèves de cacao marchandes | D9: Côte d'Ivoire | E9: 2019/20 | F9: Campagne intermédiaire (avr.-sept.) | G9: Prix minimum garanti (administré) | H9: Bord champ | I9: Bien fermenté, séché, trié (grade marchand) | J9: 825 | K9: XOF | L9: kg | M9: 1 | N9: 2020-04:2020-09 | O9: =IF(K9="USD",1,INDEX(Change_periodes!$D$1:$N$400,MATCH($N9,Change_periodes!$A$1:$A$400,0),MATCH($K9,Change_periodes!$D$1:$N$1,0))) -> 578.5804 | P9: BCE (parité fixe 655,957 FCFA/EUR) | Q9: =INDEX(Change_periodes!$D$1:$D$400,MATCH($N9,Change_periodes!$A$1:$A$400,0)) -> 578.5804 | R9: =IFERROR(J9/M9/O9,"") -> 1.4259038 | S9: =IFERROR(R9*Q9,"") -> 825 | T9: 1 | U9: FCFA/kg de produit tel que vendu | V9: =IFERROR(S9/T9,"") -> 825 | W9: INT-CAC-2019/20-I | X9: =IF(W9="","",IFERROR(INDEX($V$1:$V$178,MATCH(W9,$A$1:$A$178,0)),"")) -> 1323.3272 | Y9: =IF(OR(X9="",V9=""),"",V9/X9) -> 0.6234286 | AA9: =IF(Z9="","",IFERROR(INDEX($V$1:$V$178,MATCH(Z9,$A$1:$A$178,0)),"")) | AB9: =IF(OR(AA9="",V9=""),"",V9/AA9) | AC9: CCC (via Connectionivoirienne) – Le prix bord champ du cacao maintenu à 825 FCFA/kg pour la petite traite (le prix de marché aurait été de 625 FCFA) | AD9: https://connectionivoirienne.net/2020/04/01/le-prix-bord-champ-du-cacao-maintenu-a-825-fcfa-kg-pour-la-petite-traite-en-cote-divoire/ | AE9: 2026-10-01 | AF9: B | AG9: Prix administré par le CCC ; ventes anticipées ; règle ≥60 % du prix CAF de référence
A10: CAC-CI-2020/21-P | B10: Cacao | C10: Fèves de cacao marchandes | D10: Côte d'Ivoire | E10: 2020/21 | F10: Campagne principale (oct.-mars) | G10: Prix minimum garanti (administré) | H10: Bord champ | I10: Bien fermenté, séché, trié (grade marchand) | J10: 1000 | K10: XOF | L10: kg | M10: 1 | N10: 2020-10:2021-03 | O10: =IF(K10="USD",1,INDEX(Change_periodes!$D$1:$N$400,MATCH($N10,Change_periodes!$A$1:$A$400,0),MATCH($K10,Change_periodes!$D$1:$N$1,0))) -> 547.10364 | P10: BCE (parité fixe 655,957 FCFA/EUR) | Q10: =INDEX(Change_periodes!$D$1:$D$400,MATCH($N10,Change_periodes!$A$1:$A$400,0)) -> 547.10364 | R10: =IFERROR(J10/M10/O10,"") -> 1.8278073 | S10: =IFERROR(R10*Q10,"") -> 1000 | T10: 1 | U10: FCFA/kg de produit tel que vendu | V10: =IFERROR(S10/T10,"") -> 1000 | W10: INT-CAC-2020/21-P | X10: =IF(W10="","",IFERROR(INDEX($V$1:$V$178,MATCH(W10,$A$1:$A$178,0)),"")) -> 1305.3537 | Y10: =IF(OR(X10="",V10=""),"",V10/X10) -> 0.76607588 | AA10: =IF(Z10="","",IFERROR(INDEX($V$1:$V$178,MATCH(Z10,$A$1:$A$178,0)),"")) | AB10: =IF(OR(AA10="",V10=""),"",V10/AA10) | AC10: CCC (via BusinessWorld/Reuters) – Ivory Coast raises 2020/21 cocoa farmgate price by 21% (1 000 FCFA/kg) | AD10: https://www.pressreader.com/philippines/business-world/20201005/281676847366265 | AE10: 2026-10-01 | AF10: B | AG10: Prix administré par le CCC ; ventes anticipées ; règle ≥60 % du prix CAF de référence
A11: CAC-CI-2020/21-I | B11: Cacao | C11: Fèves de cacao marchandes | D11: Côte d'Ivoire | E11: 2020/21 | F11: Campagne intermédiaire (avr.-sept.) | G11: Prix minimum garanti (administré) | H11: Bord champ | I11: Bien fermenté, séché, trié (grade marchand) | J11: 750 | K11: XOF | L11: kg | M11: 1 | N11: 2021-04:2021-09 | O11: =IF(K11="USD",1,INDEX(Change_periodes!$D$1:$N$400,MATCH($N11,Change_periodes!$A$1:$A$400,0),MATCH($K11,Change_periodes!$D$1:$N$1,0))) -> 550.25616 | P11: BCE (parité fixe 655,957 FCFA/EUR) | Q11: =INDEX(Change_periodes!$D$1:$D$400,MATCH($N11,Change_periodes!$A$1:$A$400,0)) -> 550.25616 | R11: =IFERROR(J11/M11/O11,"") -> 1.3630015 | S11: =IFERROR(R11*Q11,"") -> 750 | T11: 1 | U11: FCFA/kg de produit tel que vendu | V11: =IFERROR(S11/T11,"") -> 750 | W11: INT-CAC-2020/21-I | X11: =IF(W11="","",IFERROR(INDEX($V$1:$V$178,MATCH(W11,$A$1:$A$178,0)),"")) -> 1331.3374 | Y11: =IF(OR(X11="",V11=""),"",V11/X11) -> 0.56334328 | AA11: =IF(Z11="","",IFERROR(INDEX($V$1:$V$178,MATCH(Z11,$A$1:$A$178,0)),"")) | AB11: =IF(OR(AA11="",V11=""),"",V11/AA11) | AC11: CCC (via KOACI) – Cacao : le Conseil fixe le kg de la fève à 750 FCFA pour la campagne intermédiaire | AD11: https://www.koaci.com/index.php/article/2021/03/31/cote-divoire/politique/cote-divoire-cacao-le-conseil-fixe-le-kg-de-la-feve-a-750-fcfa-pour-la-campagne-intermediaire_149966.html | AE11: 2026-10-01 | AF11: B | AG11: Prix administré par le CCC ; ventes anticipées ; règle ≥60 % du prix CAF de référence
A12: CAC-CI-2021/22-P | B12: Cacao | C12: Fèves de cacao marchandes | D12: Côte d'Ivoire | E12: 2021/22 | F12: Campagne principale (oct.-mars) | G12: Prix minimum garanti (administré) | H12: Bord champ | I12: Bien fermenté, séché, trié (grade marchand) | J12: 825 | K12: XOF | L12: kg | M12: 1 | N12: 2021-10:2022-03 | O12: =IF(K12="USD",1,INDEX(Change_periodes!$D$1:$N$400,MATCH($N12,Change_periodes!$A$1:$A$400,0),MATCH($K12,Change_periodes!$D$1:$N$1,0))) -> 578.96606 | P12: BCE (parité fixe 655,957 FCFA/EUR) | Q12: =INDEX(Change_periodes!$D$1:$D$400,MATCH($N12,Change_periodes!$A$1:$A$400,0)) -> 578.96606 | R12: =IFERROR(J12/M12/O12,"") -> 1.424954 | S12: =IFERROR(R12*Q12,"") -> 825 | T12: 1 | U12: FCFA/kg de produit tel que vendu | V12: =IFERROR(S12/T12,"") -> 825 | W12: INT-CAC-2021/22-P | X12: =IF(W12="","",IFERROR(INDEX($V$1:$V$178,MATCH(W12,$A$1:$A$178,0)),"")) -> 1430.1041 | Y12: =IF(OR(X12="",V12=""),"",V12/X12) -> 0.5768811 | AA12: =IF(Z12="","",IFERROR(INDEX($V$1:$V$178,MATCH(Z12,$A$1:$A$178,0)),"")) | AB12: =IF(OR(AA12="",V12=""),"",V12/AA12) | AC12: CCC (via Connectionivoirienne) – Le prix bord-champ du café fixé à 700 FCFA/kg, le cacao à 825 FCFA | AD12: https://connectionivoirienne.net/2021/10/01/le-prix-bord-champ-du-cafe-fixe-a-700-fcfa-kg/ | AE12: 2026-10-01 | AF12: B | AG12: Prix administré par le CCC ; ventes anticipées ; règle ≥60 % du prix CAF de référence
A13: CAC-CI-2021/22-I | B13: Cacao | C13: Fèves de cacao marchandes | D13: Côte d'Ivoire | E13: 2021/22 | F13: Campagne intermédiaire (avr.-sept.) | G13: Prix minimum garanti (administré) | H13: Bord champ | I13: Bien fermenté, séché, trié (grade marchand) | J13: 825 | K13: XOF | L13: kg | M13: 1 | N13: 2022-04:2022-09 | O13: =IF(K13="USD",1,INDEX(Change_periodes!$D$1:$N$400,MATCH($N13,Change_periodes!$A$1:$A$400,0),MATCH($K13,Change_periodes!$D$1:$N$1,0))) -> 633.60467 | P13: BCE (parité fixe 655,957 FCFA/EUR) | Q13: =INDEX(Change_periodes!$D$1:$D$400,MATCH($N13,Change_periodes!$A$1:$A$400,0)) -> 633.60467 | R13: =IFERROR(J13/M13/O13,"") -> 1.3020737 | S13: =IFERROR(R13*Q13,"") -> 825 | T13: 1 | U13: FCFA/kg de produit tel que vendu | V13: =IFERROR(S13/T13,"") -> 825 | W13: INT-CAC-2021/22-I | X13: =IF(W13="","",IFERROR(INDEX($V$1:$V$178,MATCH(W13,$A$1:$A$178,0)),"")) -> 1478.9463 | Y13: =IF(OR(X13="",V13=""),"",V13/X13) -> 0.55782959 | AA13: =IF(Z13="","",IFERROR(INDEX($V$1:$V$178,MATCH(Z13,$A$1:$A$178,0)),"")) | AB13: =IF(OR(AA13="",V13=""),"",V13/AA13) | AC13: CCC (via Abidjan.net) – Le prix du kg de cacao pour la campagne intermédiaire maintenu à 825 FCFA | AD13: https://news.abidjan.net/articles/706140/cote-divoire-le-prix-du-kg-de-cacao-pour-la-campagne-intermediaire-maintenu-a-825-fcfa | AE13: 2026-10-01 | AF13: B | AG13: Prix administré par le CCC ; ventes anticipées ; règle ≥60 % du prix CAF de référence
... A42: CAC-CI-2026/27-P | B42: Cacao | C42: Fèves de cacao marchandes | D42: Côte d'Ivoire | E42: 2026/27 | F42: Ouverture campagne principale (annonce 01/09/2026) | G42: Prix minimum garanti (administré) | H42: Bord champ | I42: Bien fermenté, séché, trié | J42: 1200 | K42: XOF | L42: kg | M42: 1 | N42: 2026-09:2026-09 | O42: =IF(K42="USD",1,INDEX(Change_periodes!$D$1:$N$400,MATCH($N42,Change_periodes!$A$1:$A$400,0),MATCH($K42,Change_periodes!$D$1:$N$1,0))) -> 565.22679 | P42: BCE (parité fixe 655,957 FCFA/EUR) | Q42: =INDEX(Change_periodes!$D$1:$D$400,MATCH($N42,Change_periodes!$A$1:$A$400,0)) -> 565.22679 | R42: =IFERROR(J42/M42/O42,"") -> 2.1230416 | S42: =IFERROR(R42*Q42,"") -> 1200 | T42: 1 | U42: FCFA/kg de produit tel que vendu | V42: =IFERROR(S42/T42,"") -> 1200 | W42: INT-CAC-2026-08 | X42: =IF(W42="","",IFERROR(INDEX($V$1:$V$178,MATCH(W42,$A$1:$A$178,0)),"")) -> 3387.5448 | Y42: =IF(OR(X42="",V42=""),"",V42/X42) -> 0.35423886 | AA42: =IF(Z42="","",IFERROR(INDEX($V$1:$V$178,MATCH(Z42,$A$1:$A$178,0)),"")) | AB42: =IF(OR(AA42="",V42=""),"",V42/AA42) | AC42: Gouvernement de Côte d'Ivoire (portail officiel) – Campagne principale 2026-2027 : cacao 1 200 FCFA/kg, café 1 300 FCFA/kg | AD42: https://gouv.ci/actualite/campagne-principale-2026-2027-le-prix-bord-champ-du-cacao-est-fixe-a-1200-fcfa-le-kg-le-prix-du-cafe-setablit-a-1300-fcfa-le-kg-8771 | AE42: 2026-10-01 | AF42: A | AG42: Fondé sur >1,1 Mt de ventes anticipées conclues mars-juin 2026, au creux du marché
A43: CAC-GH-2026/27-P | B43: Cacao | C43: Fèves de cacao marchandes | D43: Ghana | E43: 2026/27 | F43: Ouverture campagne (effet 25/09/2026) | G43: Prix producteur fixé (COCOBOD) | H43: Bord champ (centres d'achat LBC) | I43: Grade I/II | J43: 42400 | K43: GHS | L43: tonne | M43: 1000 | N43: 2026-09:2026-09 | O43: =IF(K43="USD",1,INDEX(Change_periodes!$D$1:$N$400,MATCH($N43,Change_periodes!$A$1:$A$400,0),MATCH($K43,Change_periodes!$D$1:$N$1,0))) -> 11.49 | P43: BRI / Banque du Ghana (moyenne de période) | Q43: =INDEX(Change_periodes!$D$1:$D$400,MATCH($N43,Change_periodes!$A$1:$A$400,0)) -> 565.22679 | R43: =IFERROR(J43/M43/O43,"") -> 3.6901654 | S43: =IFERROR(R43*Q43,"") -> 2085.7803 | T43: 1 | U43: FCFA/kg de produit tel que vendu | V43: =IFERROR(S43/T43,"") -> 2085.7803 | W43: INT-CAC-2026-08 | X43: =IF(W43="","",IFERROR(INDEX($V$1:$V$178,MATCH(W43,$A$1:$A$178,0)),"")) -> 3387.5448 | Y43: =IF(OR(X43="",V43=""),"",V43/X43) -> 0.61572037 | Z43: FOB-GH-CAC-2026/27 | AA43: =IF(Z43="","",IFERROR(INDEX($V$1:$V$178,MATCH(Z43,$A$1:$A$178,0)),"")) -> 2930.2899 | AB43: =IF(OR(AA43="",V43=""),"",V43/AA43) -> 0.7118 | AC43: COCOBOD (via MyJoyOnline) – Producer price GH¢42 400/t for 2026/27 (71,18 % du FOB brut réalisé ; Act 1182 : minimum 70 %) | AD43: https://www.myjoyonline.com/cocobod-increases-cocoa-producer-price-to-gh%C2%A242400-for-2026-27-season/ | AE43: 2026-10-01 | AF43: B | AG43: 71,18 % du FOB brut réalisé (Act 1182 : minimum 70 %) ; GH¢2 650/sac de 64 kg
A44: FOB-GH-CAC-2026/27 | B44: Cacao | C44: Fèves de cacao (valeur FOB brute réalisée) | D44: Ghana | E44: 2026/27 | F44: Ventes de la campagne 2026/27 | G44: Valeur FOB brute réalisée (dérivée) | H44: FOB Tema/Takoradi | I44: Grade I/II | J44: =42400/0.7118 -> 59567.294 | K44: GHS | L44: tonne | M44: 1000 | N44: 2026-09:2026-09 | O44: =IF(K44="USD",1,INDEX(Change_periodes!$D$1:$N$400,MATCH($N44,Change_periodes!$A$1:$A$400,0),MATCH($K44,Change_periodes!$D$1:$N$1,0))) -> 11.49 | P44: BRI / Banque du Ghana (moyenne de période) | Q44: =INDEX(Change_periodes!$D$1:$D$400,MATCH($N44,Change_periodes!$A$1:$A$400,0)) -> 565.22679 | R44: =IFERROR(J44/M44/O44,"") -> 5.1842728 | S44: =IFERROR(R44*Q44,"") -> 2930.2899 | T44: 1 | U44: FCFA/kg de produit tel que vendu | V44: =IFERROR(S44/T44,"") -> 2930.2899 | X44: =IF(W44="","",IFERROR(INDEX($V$1:$V$178,MATCH(W44,$A$1:$A$178,0)),"")) | Y44: =IF(OR(X44="",V44=""),"",V44/X44) | AA44: =IF(Z44="","",IFERROR(INDEX($V$1:$V$178,MATCH(Z44,$A$1:$A$178,0)),"")) | AB44: =IF(OR(AA44="",V44=""),"",V44/AA44) | AC44: COCOBOD (via MyJoyOnline) – Producer price GH¢42 400/t for 2026/27 (71,18 % du FOB brut réalisé ; Act 1182 : minimum 70 %) | AD44: https://www.myjoyonline.com/cocobod-increases-cocoa-producer-price-to-gh%C2%A242400-for-2026-27-season/ | AE44: 2026-10-01 | AF44: B | AG44: Dérivé : prix producteur ÷ 71,18 % (part déclarée par le COCOBOD)
A45: CAC-CM-2026-04 | B45: Cacao | C45: Fèves de cacao marchandes | D45: Cameroun | E45: 2025/26 | F45: Mars-avril 2026 | G45: Prix de marché (libéralisé, relevé ONCC-SIF) | H45: Bord champ (bassins de production) | I45: Fèves marchandes (qualité variable) | J45: =(1200+1450)/2 -> 1325 | K45: XAF | L45: kg | M45: 1 | N45: 2026-03:2026-04 | O45: =IF(K45="USD",1,INDEX(Change_periodes!$D$1:$N$400,MATCH($N45,Change_periodes!$A$1:$A$400,0),MATCH($K45,Change_periodes!$D$1:$N$1,0))) -> 563.92991 | P45: BCE (parité fixe 655,957 FCFA/EUR) | Q45: =INDEX(Change_periodes!$D$1:$D$400,MATCH($N45,Change_periodes!$A$1:$A$400,0)) -> 563.92991 | R45: =IFERROR(J45/M45/O45,"") -> 2.3495828 | S45: =IFERROR(R45*Q45,"") -> 1325 | T45: 1 | U45: FCFA/kg de produit tel que vendu | V45: =IFERROR(S45/T45,"") -> 1325 | W45: INT-CAC-2026-04 | X45: =IF(W45="","",IFERROR(INDEX($V$1:$V$178,MATCH(W45,$A$1:$A$178,0)),"")) -> 1870.4512 | Y45: =IF(OR(X45="",V45=""),"",V45/X45) -> 0.70838523 | AA45: =IF(Z45="","",IFERROR(INDEX($V$1:$V$178,MATCH(Z45,$A$1:$A$178,0)),"")) | AB45: =IF(OR(AA45="",V45=""),"",V45/AA45) | AC45: ONCC-SIF (via Invest-Time) – Cacao au Cameroun : 1 200-1 450 FCFA/kg dans les bassins (mars-avril 2026) | AD45: https://invest-time.com/2026/05/07/cacao-cameroun-prix-campagne/ | AE45: 2026-10-01 | AF45: B | AG45: Milieu de la fourchette 1200-1450 FCFA/kg ; XAF = XOF (même parité avec l'euro)
A46: CAC-CM-2026-05 | B46: Cacao | C46: Fèves de cacao marchandes | D46: Cameroun | E46: 2025/26 | F46: Début mai 2026 | G46: Prix de marché (libéralisé, relevé ONCC-SIF) | H46: Bord champ (bassins de production) | I46: Fèves marchandes (qualité variable) | J46: =(1550+1650)/2 -> 1600 | K46: XAF | L46: kg | M46: 1 | N46: 2026-05:2026-05 | O46: =IF(K46="USD",1,INDEX(Change_periodes!$D$1:$N$400,MATCH($N46,Change_periodes!$A$1:$A$400,0),MATCH($K46,Change_periodes!$D$1:$N$1,0))) -> 561.93417 | P46: BCE (parité fixe 655,957 FCFA/EUR) | Q46: =INDEX(Change_periodes!$D$1:$D$400,MATCH($N46,Change_periodes!$A$1:$A$400,0)) -> 561.93417 | R46: =IFERROR(J46/M46/O46,"") -> 2.8473086 | S46: =IFERROR(R46*Q46,"") -> 1600 | T46: 1 | U46: FCFA/kg de produit tel que vendu | V46: =IFERROR(S46/T46,"") -> 1600 | W46: INT-CAC-2026-05 | X46: =IF(W46="","",IFERROR(INDEX($V$1:$V$178,MATCH(W46,$A$1:$A$178,0)),"")) -> 2328.0764 | Y46: =IF(OR(X46="",V46=""),"",V46/X46) -> 0.68726266 | AA46: =IF(Z46="","",IFERROR(INDEX($V$1:$V$178,MATCH(Z46,$A$1:$A$178,0)),"")) | AB46: =IF(OR(AA46="",V46=""),"",V46/AA46) | AC46: ONCC-SIF (via Investir au Cameroun) – Le prix du kilogramme repasse au-dessus de 1 500 FCFA (1 550-1 650) | AD46: https://www.investiraucameroun.com/agriculture/0705-23372-cacao-le-prix-du-kilogramme-repasse-au-dessus-de-1-500-fcfa-a-deux-mois-de-la-fin-de-campagne | AE46: 2026-10-01 | AF46: B | AG46: Milieu de la fourchette 1550-1650 FCFA/kg ; XAF = XOF (même parité avec l'euro)
A47: CAC-CM-2026-06 | B47: Cacao | C47: Fèves de cacao marchandes | D47: Cameroun | E47: 2025/26 | F47: 30 juin 2026 | G47: Prix de marché (libéralisé, relevé ONCC-SIF) | H47: Bord champ (bassins de production) | I47: Fèves marchandes (qualité variable) | J47: =(2100+2250)/2 -> 2175 | K47: XAF | L47: kg | M47: 1 | N47: 2026-06:2026-06 | O47: =IF(K47="USD",1,INDEX(Change_periodes!$D$1:$N$400,MATCH($N47,Change_periodes!$A$1:$A$400,0),MATCH($K47,Change_periodes!$D$1:$N$1,0))) -> 569.50599 | P47: BCE (parité fixe 655,957 FCFA/EUR) | Q47: =INDEX(Change_periodes!$D$1:$D$400,MATCH($N47,Change_periodes!$A$1:$A$400,0)) -> 569.50599 | R47: =IFERROR(J47/M47/O47,"") -> 3.8190994 | S47: =IFERROR(R47*Q47,"") -> 2175 | T47: 1 | U47: FCFA/kg de produit tel que vendu | V47: =IFERROR(S47/T47,"") -> 2175 | W47: INT-CAC-2026-06 | X47: =IF(W47="","",IFERROR(INDEX($V$1:$V$178,MATCH(W47,$A$1:$A$178,0)),"")) -> 2503.2408 | Y47: =IF(OR(X47="",V47=""),"",V47/X47) -> 0.86887366 | AA47: =IF(Z47="","",IFERROR(INDEX($V$1:$V$178,MATCH(Z47,$A$1:$A$178,0)),"")) | AB47: =IF(OR(AA47="",V47=""),"",V47/AA47) | AC47: ONCC-SIF (via Investir au Cameroun) – Le prix aux producteurs atteint 2 250 FCFA (2 100-2 250 au 30/06/2026) | AD47: https://www.investiraucameroun.com/agriculture/3006-23552-cacao-le-prix-aux-producteurs-atteint-2250-fcfa-son-plus-haut-niveau-depuis-le-debut-de-la-campagne-2025-2026 | AE47: 2026-10-01 | AF47: B | AG47: Milieu de la fourchette 2100-2250 FCFA/kg ; XAF = XOF (même parité avec l'euro)
A48: CAC-NG-2026-09 | B48: Cacao | C48: Fèves de cacao | D48: Nigeria | E48: 2026/27 | F48: 25/09/2026 | G48: Prix de marché (libéralisé) | H48: Bord champ (indicatif) | I48: Non précisée | J48: 5728.5 | K48: NGN | L48: kg | M48: 1 | N48: 2026-09:2026-09 | O48: =IF(K48="USD",1,INDEX(Change_periodes!$D$1:$N$400,MATCH($N48,Change_periodes!$A$1:$A$400,0),MATCH($K48,Change_periodes!$D$1:$N$1,0))) -> 1328.81 | P48: Implicite source (C) | Q48: =INDEX(Change_periodes!$D$1:$D$400,MATCH($N48,Change_periodes!$A$1:$A$400,0)) -> 565.22679 | R48: =IFERROR(J48/M48/O48,"") -> 4.311 | S48: =IFERROR(R48*Q48,"") -> 2436.6927 | T48: 1 | U48: FCFA/kg de produit tel que vendu | V48: =IFERROR(S48/T48,"") -> 2436.6927 | W48: INT-CAC-2026-08 | X48: =IF(W48="","",IFERROR(INDEX($V$1:$V$178,MATCH(W48,$A$1:$A$178,0)),"")) -> 3387.5448 | Y48: =IF(OR(X48="",V48=""),"",V48/X48) -> 0.71930937 | AA48: =IF(Z48="","",IFERROR(INDEX($V$1:$V$178,MATCH(Z48,$A$1:$A$178,0)),"")) | AB48: =IF(OR(AA48="",V48=""),"",V48/AA48) | AC48: Mansa Markets – Nigeria farmgate 5 728,5 NGN/kg (≈4 311 USD/t), 25/09/2026 | AD48: https://www.mansamarkets.com/blog/cocoa-farmgate-price-vs-world-price | AE48: 2026-10-01 | AF48: C | AG48: Source secondaire ; taux de change implicite de la source ; à titre indicatif uniquement
A49: CAC-EC-2026-01 | B49: Cacao | C49: Fèves de cacao sèches (CCN-51 / Nacional) | D49: Équateur | E49: 2025/26 | F49: Janvier 2026 | G49: Prix de marché (libéralisé) | H49: Bord champ | I49: Après décotes usuelles (qualité variable) | J49: =(180+190)/2 -> 185 | K49: USD | L49: quintal (100 lb) | M49: 45.3592 | N49: 2026-01:2026-01 | O49: =IF(K49="USD",1,INDEX(Change_periodes!$D$1:$N$400,MATCH($N49,Change_periodes!$A$1:$A$400,0),MATCH($K49,Change_periodes!$D$1:$N$1,0))) -> 1 | P49: — | Q49: =INDEX(Change_periodes!$D$1:$D$400,MATCH($N49,Change_periodes!$A$1:$A$400,0)) -> 558.82057 | R49: =IFERROR(J49/M49/O49,"") -> 4.0785552 | S49: =IFERROR(R49*Q49,"") -> 2279.1805 | T49: 1 | U49: FCFA/kg de produit tel que vendu | V49: =IFERROR(S49/T49,"") -> 2279.1805 | W49: INT-CAC-2026-01 | X49: =IF(W49="","",IFERROR(INDEX($V$1:$V$178,MATCH(W49,$A$1:$A$178,0)),"")) -> 2778.7353 | Y49: =IF(OR(X49="",V49=""),"",V49/X49) -> 0.82022226 | AA49: =IF(Z49="","",IFERROR(INDEX($V$1:$V$178,MATCH(Z49,$A$1:$A$178,0)),"")) | AB49: =IF(OR(AA49="",V49=""),"",V49/AA49) | AC49: El Universo – Les producteurs reçoivent 180-190 USD/quintal (janv. 2026) | AD49: https://www.eluniverso.com/noticias/economia/precio-cacao-ecuador-exportador-productor-nota/ | AE49: 2026-10-01 | AF49: B | AG49: Milieu de fourchette 180-190 USD/qq
A50: CAC-EC-2026-02 | B50: Cacao | C50: Fèves de cacao sèches | D50: Équateur | E50: 2025/26 | F50: Février 2026 | G50: Prix de marché (libéralisé) | H50: Centres de collecte principaux | I50: Qualité variable | J50: 100 | K50: USD | L50: quintal (100 lb) | M50: 45.3592 | N50: 2026-02:2026-02 | O50: =IF(K50="USD",1,INDEX(Change_periodes!$D$1:$N$400,MATCH($N50,Change_periodes!$A$1:$A$400,0),MATCH($K50,Change_periodes!$D$1:$N$1,0))) -> 1 | P50: — | Q50: =INDEX(Change_periodes!$D$1:$D$400,MATCH($N50,Change_periodes!$A$1:$A$400,0)) -> 554.76977 | R50: =IFERROR(J50/M50/O50,"") -> 2.2046244 | S50: =IFERROR(R50*Q50,"") -> 1223.059 | T50: 1 | U50: FCFA/kg de produit tel que vendu | V50: =IFERROR(S50/T50,"") -> 1223.059 | W50: INT-CAC-2026-02 | X50: =IF(W50="","",IFERROR(INDEX($V$1:$V$178,MATCH(W50,$A$1:$A$178,0)),"")) -> 1990.0646 | Y50: =IF(OR(X50="",V50=""),"",V50/X50) -> 0.61458256 | AA50: =IF(Z50="","",IFERROR(INDEX($V$1:$V$178,MATCH(Z50,$A$1:$A$178,0)),"")) | AB50: =IF(OR(AA50="",V50=""),"",V50/AA50) | AC50: Al Día (Équateur) – Le cacao revient à 100 USD le quintal (80-85 USD dans les petits cantons), fév. 2026 | AD50: https://www.aldia.com.ec/el-cacao-regresa-a-niveles-de-2023-100-el-quintal-y-en-cantones-pequenos-llega-a-80/ | AE50: 2026-10-01 | AF50: B | AG50: 80-85 USD/qq dans les petits cantons
A51: CAF-CI-2016/17 | B51: Café | C51: Café vert robusta (décortiqué) | D51: Côte d'Ivoire | E51: 2016/17 | F51: Campagne (oct.-sept.) | G51: Prix minimum garanti (administré) | H51: Bord champ | I51: Bien séché, décortiqué, trié | J51: 750 | K51: XOF | L51: kg | M51: 1 | N51: 2016-10:2017-09 | O51: =IF(K51="USD",1,INDEX(Change_periodes!$D$1:$N$400,MATCH($N51,Change_periodes!$A$1:$A$400,0),MATCH($K51,Change_periodes!$D$1:$N$1,0))) -> 594.82193 | P51: BCE (parité fixe 655,957 FCFA/EUR) | Q51: =INDEX(Change_periodes!$D$1:$D$400,MATCH($N51,Change_periodes!$A$1:$A$400,0)) -> 594.82193 | R51: =IFERROR(J51/M51/O51,"") -> 1.2608816 | S51: =IFERROR(R51*Q51,"") -> 750 | T51: 1 | U51: FCFA/kg de produit tel que vendu | V51: =IFERROR(S51/T51,"") -> 750 | W51: INT-ROB-2016/17 | X51: =IF(W51="","",IFERROR(INDEX($V$1:$V$178,MATCH(W51,$A$1:$A$178,0)),"")) -> 1358.6634 | Y51: =IF(OR(X51="",V51=""),"",V51/X51) -> 0.55201308 | AA51: =IF(Z51="","",IFERROR(INDEX($V$1:$V$178,MATCH(Z51,$A$1:$A$178,0)),"")) | AB51: =IF(OR(AA51="",V51=""),"",V51/AA51) | AC51: CCC (via Connectionivoirienne) – Le prix du kg de café reste inchangé à 750 FCFA pour la campagne 2017-2018 | AD51: https://connectionivoirienne.net/2017/12/21/cote-divoire-le-prix-du-kg-de-cafe-reste-inchange-a-750-fcfa-pour-la-campagne-2017-2018/ | AE51: 2026-10-01 | AF51: B | AG51: Prix 2016/17 déduit du maintien à 750 FCFA en 2017/18 (« inchangé ») ; Avant 2021/22 la campagne café s'ouvrait en décembre : moyenne oct.-sept. utilisée par homogénéité
A52: CAF-CI-2017/18 | B52: Café | C52: Café vert robusta (décortiqué) | D52: Côte d'Ivoire | E52: 2017/18 | F52: Campagne (oct.-sept.) | G52: Prix minimum garanti (administré) | H52: Bord champ | I52: Bien séché, décortiqué, trié | J52: 750 | K52: XOF | L52: kg | M52: 1 | N52: 2017-10:2018-09 | O52: =IF(K52="USD",1,INDEX(Change_periodes!$D$1:$N$400,MATCH($N52,Change_periodes!$A$1:$A$400,0),MATCH($K52,Change_periodes!$D$1:$N$1,0))) -> 551.24592 | P52: BCE (parité fixe 655,957 FCFA/EUR) | Q52: =INDEX(Change_periodes!$D$1:$D$400,MATCH($N52,Change_periodes!$A$1:$A$400,0)) -> 551.24592 | R52: =IFERROR(J52/M52/O52,"") -> 1.3605543 | S52: =IFERROR(R52*Q52,"") -> 750 | T52: 1 | U52: FCFA/kg de produit tel que vendu | V52: =IFERROR(S52/T52,"") -> 750 | W52: INT-ROB-2017/18 | X52: =IF(W52="","",IFERROR(INDEX($V$1:$V$178,MATCH(W52,$A$1:$A$178,0)),"")) -> 1061.7159 | Y52: =IF(OR(X52="",V52=""),"",V52/X52) -> 0.70640364 | AA52: =IF(Z52="","",IFERROR(INDEX($V$1:$V$178,MATCH(Z52,$A$1:$A$178,0)),"")) | AB52: =IF(OR(AA52="",V52=""),"",V52/AA52) | AC52: CCC (via Connectionivoirienne) – Le prix du kg de café reste inchangé à 750 FCFA pour la campagne 2017-2018 | AD52: https://connectionivoirienne.net/2017/12/21/cote-divoire-le-prix-du-kg-de-cafe-reste-inchange-a-750-fcfa-pour-la-campagne-2017-2018/ | AE52: 2026-10-01 | AF52: B | AG52: Avant 2021/22 la campagne café s'ouvrait en décembre : moyenne oct.-sept. utilisée par homogénéité
A53: CAF-CI-2018/19 | B53: Café | C53: Café vert robusta (décortiqué) | D53: Côte d'Ivoire | E53: 2018/19 | F53: Campagne (oct.-sept.) | G53: Prix minimum garanti (administré) | H53: Bord champ | I53: Bien séché, décortiqué, trié | J53: 700 | K53: XOF | L53: kg | M53: 1 | N53: 2018-10:2019-09 | O53: =IF(K53="USD",1,INDEX(Change_periodes!$D$1:$N$400,MATCH($N53,Change_periodes!$A$1:$A$400,0),MATCH($K53,Change_periodes!$D$1:$N$1,0))) -> 581.5558 | P53: BCE (parité fixe 655,957 FCFA/EUR) | Q53: =INDEX(Change_periodes!$D$1:$D$400,MATCH($N53,Change_periodes!$A$1:$A$400,0)) -> 581.5558 | R53: =IFERROR(J53/M53/O53,"") -> 1.2036678 | S53: =IFERROR(R53*Q53,"") -> 700 | T53: 1 | U53: FCFA/kg de produit tel que vendu | V53: =IFERROR(S53/T53,"") -> 700 | W53: INT-ROB-2018/19 | X53: =IF(W53="","",IFERROR(INDEX($V$1:$V$178,MATCH(W53,$A$1:$A$178,0)),"")) -> 976.56168 | Y53: =IF(OR(X53="",V53=""),"",V53/X53) -> 0.7168006 | AA53: =IF(Z53="","",IFERROR(INDEX($V$1:$V$178,MATCH(Z53,$A$1:$A$178,0)),"")) | AB53: =IF(OR(AA53="",V53=""),"",V53/AA53) | AC53: CCC (via Abidjan.net) – Prix du café 2018-2019 : 700 FCFA/kg (baisse de 50 FCFA) | AD53: https://news.abidjan.net/h/649843.html | AE53: 2026-10-01 | AF53: B | AG53: Avant 2021/22 la campagne café s'ouvrait en décembre : moyenne oct.-sept. utilisée par homogénéité
A54: CAF-CI-2019/20 | B54: Café | C54: Café vert robusta (décortiqué) | D54: Côte d'Ivoire | E54: 2019/20 | F54: Campagne (oct.-sept.) | G54: Prix minimum garanti (administré) | H54: Bord champ | I54: Bien séché, décortiqué, trié | J54: 700 | K54: XOF | L54: kg | M54: 1 | N54: 2019-10:2020-09 | O54: =IF(K54="USD",1,INDEX(Change_periodes!$D$1:$N$400,MATCH($N54,Change_periodes!$A$1:$A$400,0),MATCH($K54,Change_periodes!$D$1:$N$1,0))) -> 586.17851 | P54: BCE (parité fixe 655,957 FCFA/EUR) | Q54: =INDEX(Change_periodes!$D$1:$D$400,MATCH($N54,Change_periodes!$A$1:$A$400,0)) -> 586.17851 | R54: =IFERROR(J54/M54/O54,"") -> 1.1941755 | S54: =IFERROR(R54*Q54,"") -> 700 | T54: 1 | U54: FCFA/kg de produit tel que vendu | V54: =IFERROR(S54/T54,"") -> 700 | W54: INT-ROB-2019/20 | X54: =IF(W54="","",IFERROR(INDEX($V$1:$V$178,MATCH(W54,$A$1:$A$178,0)),"")) -> 891.11683 | Y54: =IF(OR(X54="",V54=""),"",V54/X54) -> 0.78553112 | AA54: =IF(Z54="","",IFERROR(INDEX($V$1:$V$178,MATCH(Z54,$A$1:$A$178,0)),"")) | AB54: =IF(OR(AA54="",V54=""),"",V54/AA54) | AC54: CCC (via Connectionivoirienne) – Café 2019-2020 fixé à 700 FCFA ; maintien permis par une subvention de 32 Mds FCFA (prix de marché : 473 FCFA) | AD54: https://connectionivoirienne.net/2019/12/26/le-prix-du-kg-de-cafe-fixe-a-700-fcfa-pour-la-campagne-2019-2020-en-cote-divoire/ | AE54: 2026-10-01 | AF54: B | AG54: Maintien financé par une subvention de 32 Mds FCFA (prix de marché estimé : 473 FCFA) ; Avant 2021/22 la campagne café s'ouvrait en décembre : moyenne oct.-sept. utilisée par homogénéité
A55: CAF-CI-2020/21 | B55: Café | C55: Café vert robusta (décortiqué) | D55: Côte d'Ivoire | E55: 2020/21 | F55: Campagne (oct.-sept.) | G55: Prix minimum garanti (administré) | H55: Bord champ | I55: Bien séché, décortiqué, trié | J55: 550 | K55: XOF | L55: kg | M55: 1 | N55: 2020-10:2021-09 | O55: =IF(K55="USD",1,INDEX(Change_periodes!$D$1:$N$400,MATCH($N55,Change_periodes!$A$1:$A$400,0),MATCH($K55,Change_periodes!$D$1:$N$1,0))) -> 548.6799 | P55: BCE (parité fixe 655,957 FCFA/EUR) | Q55: =INDEX(Change_periodes!$D$1:$D$400,MATCH($N55,Change_periodes!$A$1:$A$400,0)) -> 548.6799 | R55: =IFERROR(J55/M55/O55,"") -> 1.002406 | S55: =IFERROR(R55*Q55,"") -> 550 | T55: 1 | U55: FCFA/kg de produit tel que vendu | V55: =IFERROR(S55/T55,"") -> 550 | W55: INT-ROB-2020/21 | X55: =IF(W55="","",IFERROR(INDEX($V$1:$V$178,MATCH(W55,$A$1:$A$178,0)),"")) -> 971.59551 | Y55: =IF(OR(X55="",V55=""),"",V55/X55) -> 0.56607919 | AA55: =IF(Z55="","",IFERROR(INDEX($V$1:$V$178,MATCH(Z55,$A$1:$A$178,0)),"")) | AB55: =IF(OR(AA55="",V55=""),"",V55/AA55) | AC55: CCC (via KOACI) – Café : prix bord champ fixé à 550 FCFA/kg (campagne 2020-2021, 28/12/2020) | AD55: https://www.koaci.com/article/2020/12/23/cote-divoire/economie/cote-divoire-cafe-debut-de-la-campagne-commerciale-le-28-decembre-le-prix-bord-champ-du-kilo-fixe-a-550-fcfa-soit-une-baisse-de-155-fcfa_147642.html | AE55: 2026-10-01 | AF55: B | AG55: Campagne ouverte le 28/12/2020 ; Avant 2021/22 la campagne café s'ouvrait en décembre : moyenne oct.-sept. utilisée par homogénéité
